Workbook

Sheet README
A1: This spreadsheet was made by Ender Dempsey under the mentorship of Andrey Sarantsev, Ph.D.
A3: The SDs by Year for Deciles sheet is the data that finds the standard deviations of the data from the Kenneth R French Observatory titled "Portfolios Formed on Size [Daily]"
A4: The LNs sheet is the natural logarithms of all the values in the SDs by Year for Deciles sheet. This also includes a line graph of all the standard deviations for each decile for each year.
A5: The Correlation Matrix was done using the data from the LNs sheet.
A6: For all of the other sheets, I took the corresponding logarithms for the titular decile for each year and put them in the first column. These logarithms were soreted from low to high. Since we are testing for normality, the next columns were the ranking of the sorted logarithms, their ranking proportion, and their z-score. From this data, I made a Quantile-Quantile plot and added a linear fit line. Since the data is linear, it is log-normally distributed.

Sheet SDs by Year for Deciles
A1: Standard deviations by year for each decile | F1: Data Set: Portfolios Formed On Investment [Daily]
A3: Year | B3: Lo 10 | C3: Decile 2 | D3: Decile 3 | E3: Decile 4 | F3: Decile 5 | G3: Decile 6 | H3: Decile 7 | I3: Decile 8 | J3: Decile 9 | K3: Hi 10
A4: 1927 | B4: 1.08935 | C4: 0.80033 | D4: 0.78797 | E4: 0.66251 | F4: 0.573685 | G4: 0.634659 | H4: 0.590229 | I4: 0.57088 | J4: 0.569501 | K4: 0.518687
A5: 1928 | B5: 1.47142 | C5: 1.21873 | D5: 1.02284 | E5: 0.889978 | F5: 0.960231 | G5: 0.997491 | H5: 0.900669 | I5: 0.932362 | J5: 0.795336 | K5: 0.792328
A6: 1929 | B6: 1.83826 | C6: 1.64181 | D6: 1.70212 | E6: 1.6231 | F6: 1.74563 | G6: 1.70274 | H6: 1.82778 | I6: 1.88311 | J6: 1.8677 | K6: 1.87225
A7: 1930 | B7: 1.94341 | C7: 1.77045 | D7: 1.54825 | E7: 1.30857 | F7: 1.37749 | G7: 1.28081 | H7: 1.32643 | I7: 1.26029 | J7: 1.39601 | K7: 1.43241
A8: 1931 | B8: 2.19203 | C8: 2.23719 | D8: 1.98782 | E8: 1.65702 | F8: 1.82271 | G8: 1.94536 | H8: 1.84212 | I8: 1.95058 | J8: 2.14309 | K8: 1.97129
A9: 1932 | B9: 3.04808 | C9: 2.88369 | D9: 2.67772 | E9: 2.57235 | F9: 2.49672 | G9: 2.74158 | H9: 2.53117 | I9: 2.82368 | J9: 2.89876 | K9: 2.81024
A10: 1933 | B10: 3.39803 | C10: 3.44749 | D10: 3.31761 | E10: 3.26486 | F10: 3.09654 | G10: 3.00132 | H10: 3.01642 | I10: 2.94946 | J10: 2.84891 | K10: 2.41997
A11: 1934 | B11: 2.02163 | C11: 2.02755 | D11: 1.84777 | E11: 1.86563 | F11: 1.7723 | G11: 1.70297 | H11: 1.69914 | I11: 1.58875 | J11: 1.43969 | K11: 1.2151
A12: 1935 | B12: 1.84114 | C12: 1.63468 | D12: 1.43907 | E12: 1.41359 | F12: 1.22949 | G12: 1.28161 | H12: 1.14678 | I12: 1.05452 | J12: 1.10559 | K12: 0.866124
A13: 1936 | B13: 1.59193 | C13: 1.36285 | D13: 1.28276 | E13: 1.33363 | F13: 1.15219 | G13: 1.1424 | H13: 1.05486 | I13: 0.930189 | J13: 0.975106 | K13: 0.829422
A14: 1937 | B14: 2.79454 | C14: 2.61225 | D14: 2.32189 | E14: 2.12744 | F14: 2.12121 | G14: 1.97966 | H14: 1.99064 | I14: 1.78637 | J14: 1.83816 | K14: 1.48491
A15: 1938 | B15: 1.99764 | C15: 2.20898 | D15: 2.10723 | E15: 1.92271 | F15: 2.06261 | G15: 2.02478 | H15: 2.00243 | I15: 1.72862 | J15: 1.79698 | K15: 1.59617
... A102: 2025 | B102: 1.69966 | C102: 1.60257 | D102: 1.52854 | E102: 1.49815 | F102: 1.46977 | G102: 1.45584 | H102: 1.36137 | I102: 1.27294 | J102: 1.12492 | K102: 1.23546

Sheet LNs
A1: Natural logarithms of each data point in the last sheet
A3: {='SDs by Year for Deciles'!A3:A102} -> Year | B3: {='SDs by Year for Deciles'!B3:K3} -> Lo 10 | C3: Decile 2 | D3: Decile 3 | E3: Decile 4 | F3: Decile 5 | G3: Decile 6 | H3: Decile 7 | I3: Decile 8 | J3: Decile 9 | K3: Hi 10
A4: 1927 | B4: =LN('SDs by Year for Deciles'!B4) -> 0.085581188 | C4: =LN('SDs by Year for Deciles'!C4) -> -0.22273114 | D4: =LN('SDs by Year for Deciles'!D4) -> -0.23829526 | E4: =LN('SDs by Year for Deciles'!E4) -> -0.41171963 | F4: =LN('SDs by Year for Deciles'!F4) -> -0.55567481 | G4: =LN('SDs by Year for Deciles'!G4) -> -0.45466743 | H4: =LN('SDs by Year for Deciles'!H4) -> -0.52724468 | I4: =LN('SDs by Year for Deciles'!I4) -> -0.56057625 | ... K4: =LN('SDs by Year for Deciles'!K4) -> -0.65645466
A5: 1928 | B5: =LN('SDs by Year for Deciles'!B5) -> 0.38622792 | C5: =LN('SDs by Year for Deciles'!C5) -> 0.19780933 | D5: =LN('SDs by Year for Deciles'!D5) -> 0.022583072 | E5: =LN('SDs by Year for Deciles'!E5) -> -0.11655854 | F5: =LN('SDs by Year for Deciles'!F5) -> -0.040581398 | G5: =LN('SDs by Year for Deciles'!G5) -> -0.0025121528 | H5: =LN('SDs by Year for Deciles'!H5) -> -0.10461746 | I5: =LN('SDs by Year for Deciles'!I5) -> -0.070034128 | ... K5: =LN('SDs by Year for Deciles'!K5) -> -0.23277983
A6: 1929 | B6: =LN('SDs by Year for Deciles'!B6) -> 0.60881947 | C6: =LN('SDs by Year for Deciles'!C6) -> 0.49579929 | D6: =LN('SDs by Year for Deciles'!D6) -> 0.53187453 | E6: =LN('SDs by Year for Deciles'!E6) -> 0.4843379 | F6: =LN('SDs by Year for Deciles'!F6) -> 0.55711552 | G6: =LN('SDs by Year for Deciles'!G6) -> 0.53223872 | H6: =LN('SDs by Year for Deciles'!H6) -> 0.60310212 | I6: =LN('SDs by Year for Deciles'!I6) -> 0.63292467 | ... K6: =LN('SDs by Year for Deciles'!K6) -> 0.62714092
A7: 1930 | B7: =LN('SDs by Year for Deciles'!B7) -> 0.66444416 | C7: =LN('SDs by Year for Deciles'!C7) -> 0.57123375 | D7: =LN('SDs by Year for Deciles'!D7) -> 0.43712526 | E7: =LN('SDs by Year for Deciles'!E7) -> 0.26893494 | F7: =LN('SDs by Year for Deciles'!F7) -> 0.320263 | G7: =LN('SDs by Year for Deciles'!G7) -> 0.24749269 | H7: =LN('SDs by Year for Deciles'!H7) -> 0.28249112 | I7: =LN('SDs by Year for Deciles'!I7) -> 0.23134185 | ... K7: =LN('SDs by Year for Deciles'!K7) -> 0.35935834
A8: 1931 | B8: =LN('SDs by Year for Deciles'!B8) -> 0.78482806 | C8: =LN('SDs by Year for Deciles'!C8) -> 0.80522061 | D8: =LN('SDs by Year for Deciles'!D8) -> 0.68703856 | E8: =LN('SDs by Year for Deciles'!E8) -> 0.50502081 | F8: =LN('SDs by Year for Deciles'!F8) -> 0.6003244 | G8: =LN('SDs by Year for Deciles'!G8) -> 0.66544705 | H8: =LN('SDs by Year for Deciles'!H8) -> 0.61091708 | I8: =LN('SDs by Year for Deciles'!I8) -> 0.66812676 | ... K8: =LN('SDs by Year for Deciles'!K8) -> 0.67868815
A9: 1932 | B9: =LN('SDs by Year for Deciles'!B9) -> 1.1145119 | C9: =LN('SDs by Year for Deciles'!C9) -> 1.0590707 | D9: =LN('SDs by Year for Deciles'!D9) -> 0.98496569 | E9: =LN('SDs by Year for Deciles'!E9) -> 0.94481988 | F9: =LN('SDs by Year for Deciles'!F9) -> 0.91497787 | G9: =LN('SDs by Year for Deciles'!G9) -> 1.0085344 | H9: =LN('SDs by Year for Deciles'!H9) -> 0.92868165 | I9: =LN('SDs by Year for Deciles'!I9) -> 1.038041 | ... K9: =LN('SDs by Year for Deciles'!K9) -> 1.0332699
A10: 1933 | B10: =LN('SDs by Year for Deciles'!B10) -> 1.2231959 | C10: =LN('SDs by Year for Deciles'!C10) -> 1.2376464 | D10: =LN('SDs by Year for Deciles'!D10) -> 1.1992446 | E10: =LN('SDs by Year for Deciles'!E10) -> 1.1832169 | F10: =LN('SDs by Year for Deciles'!F10) -> 1.1302854 | G10: =LN('SDs by Year for Deciles'!G10) -> 1.0990522 | H10: =LN('SDs by Year for Deciles'!H10) -> 1.1040707 | I10: =LN('SDs by Year for Deciles'!I10) -> 1.0816221 | ... K10: =LN('SDs by Year for Deciles'!K10) -> 0.88375514
A11: 1934 | B11: =LN('SDs by Year for Deciles'!B11) -> 0.70390412 | C11: =LN('SDs by Year for Deciles'!C11) -> 0.70682817 | D11: =LN('SDs by Year for Deciles'!D11) -> 0.61397951 | E11: =LN('SDs by Year for Deciles'!E11) -> 0.6235988 | F11: =LN('SDs by Year for Deciles'!F11) -> 0.57227814 | G11: =LN('SDs by Year for Deciles'!G11) -> 0.53237379 | H11: =LN('SDs by Year for Deciles'!H11) -> 0.53012224 | I11: =LN('SDs by Year for Deciles'!I11) -> 0.46294754 | ... K11: =LN('SDs by Year for Deciles'!K11) -> 0.19482638
A12: 1935 | B12: =LN('SDs by Year for Deciles'!B12) -> 0.61038494 | C12: =LN('SDs by Year for Deciles'!C12) -> 0.49144707 | D12: =LN('SDs by Year for Deciles'!D12) -> 0.36399707 | E12: =LN('SDs by Year for Deciles'!E12) -> 0.34613257 | F12: =LN('SDs by Year for Deciles'!F12) -> 0.20659945 | G12: =LN('SDs by Year for Deciles'!G12) -> 0.2481171 | H12: =LN('SDs by Year for Deciles'!H12) -> 0.13695802 | I12: =LN('SDs by Year for Deciles'!I12) -> 0.053085687 | ... K12: =LN('SDs by Year for Deciles'!K12) -> -0.14372719
A13: 1936 | B13: =LN('SDs by Year for Deciles'!B13) -> 0.46494712 | C13: =LN('SDs by Year for Deciles'!C13) -> 0.3095781 | D13: =LN('SDs by Year for Deciles'!D13) -> 0.24901401 | E13: =LN('SDs by Year for Deciles'!E13) -> 0.28790455 | F13: =LN('SDs by Year for Deciles'!F13) -> 0.14166448 | G13: =LN('SDs by Year for Deciles'!G13) -> 0.13313131 | H13: =LN('SDs by Year for Deciles'!H13) -> 0.053408057 | I13: =LN('SDs by Year for Deciles'!I13) -> -0.072367488 | ... K13: =LN('SDs by Year for Deciles'!K13) -> -0.18702621
A14: 1937 | B14: =LN('SDs by Year for Deciles'!B14) -> 1.0276675 | C14: =LN('SDs by Year for Deciles'!C14) -> 0.96021192 | D14: =LN('SDs by Year for Deciles'!D14) -> 0.84238151 | E14: =LN('SDs by Year for Deciles'!E14) -> 0.75491938 | F14: =LN('SDs by Year for Deciles'!F14) -> 0.75198668 | G14: =LN('SDs by Year for Deciles'!G14) -> 0.68292511 | H14: =LN('SDs by Year for Deciles'!H14) -> 0.6884562 | I14: =LN('SDs by Year for Deciles'!I14) -> 0.58018563 | ... K14: =LN('SDs by Year for Deciles'!K14) -> 0.39535416
A15: 1938 | B15: =LN('SDs by Year for Deciles'!B15) -> 0.69196648 | C15: =LN('SDs by Year for Deciles'!C15) -> 0.79253087 | D15: =LN('SDs by Year for Deciles'!D15) -> 0.74537429 | E15: =LN('SDs by Year for Deciles'!E15) -> 0.65373565 | F15: =LN('SDs by Year for Deciles'!F15) -> 0.72397217 | G15: =LN('SDs by Year for Deciles'!G15) -> 0.70546105 | H15: =LN('SDs by Year for Deciles'!H15) -> 0.69436144 | I15: =LN('SDs by Year for Deciles'!I15) -> 0.5473234 | ... K15: =LN('SDs by Year for Deciles'!K15) -> 0.46760701
... A102: 2025 | B102: =LN('SDs by Year for Deciles'!B102) -> 0.53042823 | C102: =LN('SDs by Year for Deciles'!C102) -> 0.47160859 | D102: =LN('SDs by Year for Deciles'!D102) -> 0.42431303 | E102: =LN('SDs by Year for Deciles'!E102) -> 0.40423101 | F102: =LN('SDs by Year for Deciles'!F102) -> 0.38510593 | G102: =LN('SDs by Year for Deciles'!G102) -> 0.37558305 | H102: =LN('SDs by Year for Deciles'!H102) -> 0.30849155 | I102: =LN('SDs by Year for Deciles'!I102) -> 0.24132919 | ... K102: =LN('SDs by Year for Deciles'!K102) -> 0.21144337

Sheet Correlation Matrix
B1: Lo 10 | C1: Decile 2 | D1: Decile 3 | E1: Decile 4 | F1: Decile 5 | G1: Decile 6 | H1: Decile 7 | I1: Decile 8 | J1: Decile 9 | K1: Hi 10
A2: Lo 10 | B2: 1
A3: Decile 2 | B3: 0.94342954 | C3: 1
A4: Decile 3 | B4: 0.90766121 | C4: 0.98827655 | D4: 1
A5: Decile 4 | B5: 0.89488957 | C5: 0.98035638 | D5: 0.99151931 | E5: 1
A6: Decile 5 | B6: 0.86062136 | C6: 0.95877697 | D6: 0.98236712 | E6: 0.98780223 | F6: 1
A7: Decile 6 | B7: 0.8695196 | C7: 0.94957722 | D7: 0.97464872 | E7: 0.97368154 | F7: 0.98659594 | G7: 1
A8: Decile 7 | B8: 0.86520914 | C8: 0.94044229 | D8: 0.96439419 | E8: 0.96784035 | F8: 0.97950075 | G8: 0.99104713 | H8: 1
A9: Decile 8 | B9: 0.80240689 | C9: 0.90071094 | D9: 0.93536974 | E9: 0.94214352 | F9: 0.96673886 | G9: 0.97921629 | H9: 0.98584462 | I9: 1
A10: Decile 9 | B10: 0.7824981 | C10: 0.87446925 | D10: 0.90982825 | E10: 0.91779443 | F10: 0.94492025 | G10: 0.96231349 | H10: 0.97513593 | I10: 0.98929222 | J10: 1
A11: Hi 10 | B11: 0.62892966 | C11: 0.74097725 | D11: 0.79363762 | E11: 0.80887258 | F11: 0.85645816 | G11: 0.87852419 | H11: 0.89603978 | I11: 0.93660358 | J11: 0.95496071 | K11: 1

Sheet Lo 10 Test
B2: Ln of Lo 10 Sorted | C2: Rank | D2: Rank Proportion | E2: Rank-Based Z Scores
B3: =LNs!B41 -> -1.1478193 | C3: =ROW()-2 -> 1 | D3: =(C3-0.5)/99 -> 0.0050505051 | E3: =NORMSINV(D3) -> -2.5723521
B4: =LNs!B54 -> -1.0216901 | C4: =ROW()-2 -> 2 | D4: =(C4-0.5)/99 -> 0.015151515 | E4: =NORMSINV(D4) -> -2.1661068
B5: =LNs!B62 -> -0.96812628 | C5: =ROW()-2 -> 3 | D5: =(C5-0.5)/99 -> 0.025252525 | E5: =NORMSINV(D5) -> -1.9556614
B6: =LNs!B29 -> -0.93950562 | C6: =ROW()-2 -> 4 | D6: =(C6-0.5)/99 -> 0.035353535 | E6: =NORMSINV(D6) -> -1.8073542
B7: =LNs!B72 -> -0.83601805 | C7: =ROW()-2 -> 5 | D7: =(C7-0.5)/99 -> 0.045454545 | E7: =NORMSINV(D7) -> -1.6906216
B8: =LNs!B66 -> -0.82178542 | C8: =ROW()-2 -> 6 | D8: =(C8-0.5)/99 -> 0.055555556 | E8: =NORMSINV(D8) -> -1.5932188
B9: =LNs!B33 -> -0.81403202 | C9: =ROW()-2 -> 7 | D9: =(C9-0.5)/99 -> 0.065656566 | E9: =NORMSINV(D9) -> -1.5089439
B10: =LNs!B61 -> -0.79497616 | C10: =ROW()-2 -> 8 | D10: =(C10-0.5)/99 -> 0.075757576 | E10: =NORMSINV(D10) -> -1.4342002
B11: =LNs!B70 -> -0.76420719 | C11: =ROW()-2 -> 9 | D11: =(C11-0.5)/99 -> 0.085858586 | E11: =NORMSINV(D11) -> -1.366707
B12: =LNs!B65 -> -0.74244037 | C12: =ROW()-2 -> 10 | D12: =(C12-0.5)/99 -> 0.095959596 | E12: =NORMSINV(D12) -> -1.3049226
B13: =LNs!B63 -> -0.71334377 | C13: =ROW()-2 -> 11 | D13: =(C13-0.5)/99 -> 0.10606061 | E13: =NORMSINV(D13) -> -1.2477539
B14: =LNs!B40 -> -0.68339093 | C14: =ROW()-2 -> 12 | D14: =(C14-0.5)/99 -> 0.11616162 | E14: =NORMSINV(D14) -> -1.1943957
B15: =LNs!B38 -> -0.66441785 | C15: =ROW()-2 -> 13 | D15: =(C15-0.5)/99 -> 0.12626263 | E15: =NORMSINV(D15) -> -1.1442373
B16: =LNs!B53 -> -0.64682291 | C16: =ROW()-2 -> 14 | D16: =(C16-0.5)/99 -> 0.13636364 | E16: =NORMSINV(D16) -> -1.0968036
B17: =LNs!B37 -> -0.6461262 | C17: =ROW()-2 -> 15 | D17: =(C17-0.5)/99 -> 0.14646465 | E17: =NORMSINV(D17) -> -1.0517173
B18: =LNs!B71 -> -0.64372484 | C18: =ROW()-2 -> 16 | D18: =(C18-0.5)/99 -> 0.15656566 | E18: =NORMSINV(D18) -> -1.0086734
B19: =LNs!B31 -> -0.62055865 | C19: =ROW()-2 -> 17 | D19: =(C19-0.5)/99 -> 0.16666667 | E19: =NORMSINV(D19) -> -0.96742157
B20: =LNs!B69 -> -0.61628059 | C20: =ROW()-2 -> 18 | D20: =(C20-0.5)/99 -> 0.17676768 | E20: =NORMSINV(D20) -> -0.92775369
B21: =LNs!B35 -> -0.61384074 | C21: =ROW()-2 -> 19 | D21: =(C21-0.5)/99 -> 0.18686869 | E21: =NORMSINV(D21) -> -0.88949451
B22: =LNs!B36 -> -0.60840721 | C22: =ROW()-2 -> 20 | D22: =(C22-0.5)/99 -> 0.1969697 | E22: =NORMSINV(D22) -> -0.85249503
B23: =LNs!B30 -> -0.5804973 | C23: =ROW()-2 -> 21 | D23: =(C23-0.5)/99 -> 0.20707071 | E23: =NORMSINV(D23) -> -0.81662736
B24: =LNs!B42 -> -0.54990608 | C24: =ROW()-2 -> 22 | D24: =(C24-0.5)/99 -> 0.21717172 | E24: =NORMSINV(D24) -> -0.78178075
B25: =LNs!B67 -> -0.53169182 | C25: =ROW()-2 -> 23 | D25: =(C25-0.5)/99 -> 0.22727273 | E25: =NORMSINV(D25) -> -0.74785859
B26: =LNs!B68 -> -0.52157991 | C26: =ROW()-2 -> 24 | D26: =(C26-0.5)/99 -> 0.23737374 | E26: =NORMSINV(D26) -> -0.71477599
B27: =LNs!B73 -> -0.49107202 | C27: =ROW()-2 -> 25 | D27: =(C27-0.5)/99 -> 0.24747475 | E27: =NORMSINV(D27) -> -0.68245784
B28: =LNs!B49 -> -0.46696824 | C28: =ROW()-2 -> 26 | D28: =(C28-0.5)/99 -> 0.25757576 | E28: =NORMSINV(D28) -> -0.65083731
B29: =LNs!B82 -> -0.45525059 | C29: =ROW()-2 -> 27 | D29: =(C29-0.5)/99 -> 0.26767677 | E29: =NORMSINV(D29) -> -0.61985457
B30: =LNs!B74 -> -0.44958002 | C30: =ROW()-2 -> 28 | D30: =(C30-0.5)/99 -> 0.27777778 | E30: =NORMSINV(D30) -> -0.5894558
B31: =LNs!B76 -> -0.43266314 | C31: =ROW()-2 -> 29 | D31: =(C31-0.5)/99 -> 0.28787879 | E31: =NORMSINV(D31) -> -0.55959227
B32: =LNs!B52 -> -0.42073815 | C32: =ROW()-2 -> 30 | D32: =(C32-0.5)/99 -> 0.2979798 | E32: =NORMSINV(D32) -> -0.53021973
B33: =LNs!B34 -> -0.41689518 | C33: =ROW()-2 -> 31 | D33: =(C33-0.5)/99 -> 0.30808081 | E33: =NORMSINV(D33) -> -0.50129771
B34: =LNs!B60 -> -0.39712796 | C34: =ROW()-2 -> 32 | D34: =(C34-0.5)/99 -> 0.31818182 | E34: =NORMSINV(D34) -> -0.47278912
B35: =LNs!B56 -> -0.38221842 | C35: =ROW()-2 -> 33 | D35: =(C35-0.5)/99 -> 0.32828283 | E35: =NORMSINV(D35) -> -0.44465976
B36: =LNs!B59 -> -0.35146852 | C36: =ROW()-2 -> 34 | D36: =(C36-0.5)/99 -> 0.33838384 | E36: =NORMSINV(D36) -> -0.41687796
B37: =LNs!B80 -> -0.34568555 | C37: =ROW()-2 -> 35 | D37: =(C37-0.5)/99 -> 0.34848485 | E37: =NORMSINV(D37) -> -0.3894143
B38: =LNs!B32 -> -0.3322416 | C38: =ROW()-2 -> 36 | D38: =(C38-0.5)/99 -> 0.35858586 | E38: =NORMSINV(D38) -> -0.3622413
B39: =LNs!B78 -> -0.31175484 | C39: =ROW()-2 -> 37 | D39: =(C39-0.5)/99 -> 0.36868687 | E39: =NORMSINV(D39) -> -0.33533322
B40: =LNs!B94 -> -0.28549247 | C40: =ROW()-2 -> 38 | D40: =(C40-0.5)/99 -> 0.37878788 | E40: =NORMSINV(D40) -> -0.30866581
B41: =LNs!B58 -> -0.28282854 | C41: =ROW()-2 -> 39 | D41: =(C41-0.5)/99 -> 0.38888889 | E41: =NORMSINV(D41) -> -0.28221615
...

Sheet Dec 2 Test
B2: Dec 2 Sorted | C2: Rank | D2: Rank Proportion | E2: Rank-Based Z Scores
B3: =LNs!C41 -> -1.0432041 | C3: =ROW()-2 -> 1 | D3: =(C3-0.5)/99 -> 0.0050505051 | E3: =NORMSINV(D3) -> -2.5723521
B4: =LNs!C29 -> -0.90846146 | C4: =ROW()-2 -> 2 | D4: =(C4-0.5)/99 -> 0.015151515 | E4: =NORMSINV(D4) -> -2.1661068
B5: =LNs!C62 -> -0.85973556 | C5: =ROW()-2 -> 3 | D5: =(C5-0.5)/99 -> 0.025252525 | E5: =NORMSINV(D5) -> -1.9556614
B6: =LNs!C54 -> -0.82028988 | C6: =ROW()-2 -> 4 | D6: =(C6-0.5)/99 -> 0.035353535 | E6: =NORMSINV(D6) -> -1.8073542
B7: =LNs!C35 -> -0.74398795 | C7: =ROW()-2 -> 5 | D7: =(C7-0.5)/99 -> 0.045454545 | E7: =NORMSINV(D7) -> -1.6906216
B8: =LNs!C33 -> -0.7357061 | C8: =ROW()-2 -> 6 | D8: =(C8-0.5)/99 -> 0.055555556 | E8: =NORMSINV(D8) -> -1.5932188
B9: =LNs!C66 -> -0.70498295 | C9: =ROW()-2 -> 7 | D9: =(C9-0.5)/99 -> 0.065656566 | E9: =NORMSINV(D9) -> -1.5089439
B10: =LNs!C31 -> -0.69744038 | C10: =ROW()-2 -> 8 | D10: =(C10-0.5)/99 -> 0.075757576 | E10: =NORMSINV(D10) -> -1.4342002
B11: =LNs!C38 -> -0.67848322 | C11: =ROW()-2 -> 9 | D11: =(C11-0.5)/99 -> 0.085858586 | E11: =NORMSINV(D11) -> -1.366707
B12: =LNs!C61 -> -0.65544108 | C12: =ROW()-2 -> 10 | D12: =(C12-0.5)/99 -> 0.095959596 | E12: =NORMSINV(D12) -> -1.3049226
B13: =LNs!C72 -> -0.6400577 | C13: =ROW()-2 -> 11 | D13: =(C13-0.5)/99 -> 0.10606061 | E13: =NORMSINV(D13) -> -1.2477539
B14: =LNs!C37 -> -0.62768908 | C14: =ROW()-2 -> 12 | D14: =(C14-0.5)/99 -> 0.11616162 | E14: =NORMSINV(D14) -> -1.1943957
B15: =LNs!C70 -> -0.60631465 | C15: =ROW()-2 -> 13 | D15: =(C15-0.5)/99 -> 0.12626263 | E15: =NORMSINV(D15) -> -1.1442373
B16: =LNs!C40 -> -0.59708819 | C16: =ROW()-2 -> 14 | D16: =(C16-0.5)/99 -> 0.13636364 | E16: =NORMSINV(D16) -> -1.0968036
B17: =LNs!C65 -> -0.58904666 | C17: =ROW()-2 -> 15 | D17: =(C17-0.5)/99 -> 0.14646465 | E17: =NORMSINV(D17) -> -1.0517173
B18: =LNs!C36 -> -0.56555112 | C18: =ROW()-2 -> 16 | D18: =(C18-0.5)/99 -> 0.15656566 | E18: =NORMSINV(D18) -> -1.0086734
B19: =LNs!C42 -> -0.54377246 | C19: =ROW()-2 -> 17 | D19: =(C19-0.5)/99 -> 0.16666667 | E19: =NORMSINV(D19) -> -0.96742157
B20: =LNs!C53 -> -0.52697194 | C20: =ROW()-2 -> 18 | D20: =(C20-0.5)/99 -> 0.17676768 | E20: =NORMSINV(D20) -> -0.92775369
B21: =LNs!C63 -> -0.5212784 | C21: =ROW()-2 -> 19 | D21: =(C21-0.5)/99 -> 0.18686869 | E21: =NORMSINV(D21) -> -0.88949451
B22: =LNs!C30 -> -0.51530397 | C22: =ROW()-2 -> 20 | D22: =(C22-0.5)/99 -> 0.1969697 | E22: =NORMSINV(D22) -> -0.85249503
B23: =LNs!C34 -> -0.50255823 | C23: =ROW()-2 -> 21 | D23: =(C23-0.5)/99 -> 0.20707071 | E23: =NORMSINV(D23) -> -0.81662736
B24: =LNs!C71 -> -0.50036882 | C24: =ROW()-2 -> 22 | D24: =(C24-0.5)/99 -> 0.21717172 | E24: =NORMSINV(D24) -> -0.78178075
B25: =LNs!C49 -> -0.4784504 | C25: =ROW()-2 -> 23 | D25: =(C25-0.5)/99 -> 0.22727273 | E25: =NORMSINV(D25) -> -0.74785859
B26: =LNs!C60 -> -0.42367745 | C26: =ROW()-2 -> 24 | D26: =(C26-0.5)/99 -> 0.23737374 | E26: =NORMSINV(D26) -> -0.71477599
B27: =LNs!C69 -> -0.38390814 | C27: =ROW()-2 -> 25 | D27: =(C27-0.5)/99 -> 0.24747475 | E27: =NORMSINV(D27) -> -0.68245784
B28: =LNs!C28 -> -0.32537425 | C28: =ROW()-2 -> 26 | D28: =(C28-0.5)/99 -> 0.25757576 | E28: =NORMSINV(D28) -> -0.65083731
B29: =LNs!C73 -> -0.30148354 | C29: =ROW()-2 -> 27 | D29: =(C29-0.5)/99 -> 0.26767677 | E29: =NORMSINV(D29) -> -0.61985457
B30: =LNs!C32 -> -0.29169411 | C30: =ROW()-2 -> 28 | D30: =(C30-0.5)/99 -> 0.27777778 | E30: =NORMSINV(D30) -> -0.5894558
B31: =LNs!C59 -> -0.2653115 | C31: =ROW()-2 -> 29 | D31: =(C31-0.5)/99 -> 0.28787879 | E31: =NORMSINV(D31) -> -0.55959227
B32: =LNs!C44 -> -0.26332513 | C32: =ROW()-2 -> 30 | D32: =(C32-0.5)/99 -> 0.2979798 | E32: =NORMSINV(D32) -> -0.53021973
B33: =LNs!C74 -> -0.257691 | C33: =ROW()-2 -> 31 | D33: =(C33-0.5)/99 -> 0.30808081 | E33: =NORMSINV(D33) -> -0.50129771
B34: =LNs!C26 -> -0.25545112 | C34: =ROW()-2 -> 32 | D34: =(C34-0.5)/99 -> 0.31818182 | E34: =NORMSINV(D34) -> -0.47278912
B35: =LNs!C56 -> -0.24156086 | C35: =ROW()-2 -> 33 | D35: =(C35-0.5)/99 -> 0.32828283 | E35: =NORMSINV(D35) -> -0.44465976
B36: =LNs!C68 -> -0.24149338 | C36: =ROW()-2 -> 34 | D36: =(C36-0.5)/99 -> 0.33838384 | E36: =NORMSINV(D36) -> -0.41687796
B37: =LNs!C67 -> -0.23512631 | C37: =ROW()-2 -> 35 | D37: =(C37-0.5)/99 -> 0.34848485 | E37: =NORMSINV(D37) -> -0.3894143
B38: =LNs!C58 -> -0.22348736 | C38: =ROW()-2 -> 36 | D38: =(C38-0.5)/99 -> 0.35858586 | E38: =NORMSINV(D38) -> -0.3622413
B39: =LNs!C4 -> -0.22273114 | C39: =ROW()-2 -> 37 | D39: =(C39-0.5)/99 -> 0.36868687 | E39: =NORMSINV(D39) -> -0.33533322
B40: =LNs!C21 -> -0.21630449 | C40: =ROW()-2 -> 38 | D40: =(C40-0.5)/99 -> 0.37878788 | E40: =NORMSINV(D40) -> -0.30866581
B41: =LNs!C52 -> -0.19553811 | C41: =ROW()-2 -> 39 | D41: =(C41-0.5)/99 -> 0.38888889 | E41: =NORMSINV(D41) -> -0.28221615
...

Sheet Dec 3 Test
B2: Dec 3 Sorted | C2: Rank | D2: Rank Proportion | E2: Rank-Based Z Scores
B3: =LNs!D41 -> -1.0109696 | C3: 1 | D3: 0.0050505051 | E3: -2.5723521
B4: =LNs!D29 -> -0.92986748 | C4: 2 | D4: 0.015151515 | E4: -2.1661068
B5: =LNs!D31 -> -0.72093779 | C5: 3 | D5: 0.025252525 | E5: -1.9556614
B6: =LNs!D54 -> -0.72089049 | C6: 4 | D6: 0.035353535 | E6: -1.8073542
B7: =LNs!D62 -> -0.70422835 | C7: 5 | D7: 0.045454545 | E7: -1.6906216
B8: =LNs!D66 -> -0.66427988 | C8: 6 | D8: 0.055555556 | E8: -1.5932188
B9: =LNs!D33 -> -0.64069516 | C9: 7 | D9: 0.065656566 | E9: -1.5089439
B10: =LNs!D35 -> -0.62779774 | C10: 8 | D10: 0.075757576 | E10: -1.4342002
B11: =LNs!D38 -> -0.60797549 | C11: 9 | D11: 0.085858586 | E11: -1.366707
B12: =LNs!D42 -> -0.58416364 | C12: 10 | D12: 0.095959596 | E12: -1.3049226
B13: =LNs!D40 -> -0.58043118 | C13: 11 | D13: 0.10606061 | E13: -1.2477539
B14: =LNs!D36 -> -0.57576956 | C14: 12 | D14: 0.11616162 | E14: -1.1943957
B15: =LNs!D65 -> -0.56777171 | C15: 13 | D15: 0.12626263 | E15: -1.1442373
B16: =LNs!D37 -> -0.56585219 | C16: 14 | D16: 0.13636364 | E16: -1.0968036
B17: =LNs!D72 -> -0.56525189 | C17: 15 | D17: 0.14646465 | E17: -1.0517173
B18: =LNs!D49 -> -0.55092219 | C18: 16 | D18: 0.15656566 | E18: -1.0086734
B19: =LNs!D70 -> -0.52820409 | C19: 17 | D19: 0.16666667 | E19: -0.96742157
B20: =LNs!D61 -> -0.51470982 | C20: 18 | D20: 0.17676768 | E20: -0.92775369
B21: =LNs!D30 -> -0.49580073 | C21: 19 | D21: 0.18686869 | E21: -0.88949451
B22: =LNs!D69 -> -0.45587826 | C22: 20 | D22: 0.1969697 | E22: -0.85249503
B23: =LNs!D71 -> -0.44934176 | C23: 21 | D23: 0.20707071 | E23: -0.81662736
B24: =LNs!D63 -> -0.43669884 | C24: 22 | D24: 0.21717172 | E24: -0.78178075
B25: =LNs!D53 -> -0.43587432 | C25: 23 | D25: 0.22727273 | E25: -0.74785859
B26: =LNs!D19 -> -0.42446904 | C26: 24 | D26: 0.23737374 | E26: -0.71477599
B27: =LNs!D60 -> -0.42005756 | C27: 25 | D27: 0.24747475 | E27: -0.68245784
B28: =LNs!D34 -> -0.34194398 | C28: 26 | D28: 0.25757576 | E28: -0.65083731
B29: =LNs!D44 -> -0.32777655 | C29: 27 | D29: 0.26767677 | E29: -0.61985457
B30: =LNs!D28 -> -0.31667157 | C30: 28 | D30: 0.27777778 | E30: -0.5894558
B31: =LNs!D26 -> -0.29907472 | C31: 29 | D31: 0.28787879 | E31: -0.55959227
B32: =LNs!D73 -> -0.28294265 | C32: 30 | D32: 0.2979798 | E32: -0.53021973
B33: =LNs!D32 -> -0.25472194 | C33: 31 | D33: 0.30808081 | E33: -0.50129771
B34: =LNs!D21 -> -0.25358085 | C34: 32 | D34: 0.31818182 | E34: -0.47278912
B35: =LNs!D68 -> -0.2404792 | C35: 33 | D35: 0.32828283 | E35: -0.44465976
B36: =LNs!D45 -> -0.23914591 | C36: 34 | D36: 0.33838384 | E36: -0.41687796
B37: =LNs!D4 -> -0.23829526 | C37: 35 | D37: 0.34848485 | E37: -0.3894143
B38: =LNs!D58 -> -0.21354229 | C38: 36 | D38: 0.35858586 | E38: -0.3622413
B39: =LNs!D56 -> -0.20573226 | C39: 37 | D39: 0.36868687 | E39: -0.33533322
B40: =LNs!D67 -> -0.2022643 | C40: 38 | D40: 0.37878788 | E40: -0.30866581
B41: =LNs!D74 -> -0.19849972 | C41: 39 | D41: 0.38888889 | E41: -0.28221615
...

Sheet Dec 4 Test
B2: Dec 4 Sorted | C2: Rank | D2: Rank Proportion | E2: Rank-Based Z Scores
B3: =LNs!E29 -> -0.94537202 | C3: 1 | D3: 0.0050505051 | E3: -2.5723521
B4: =LNs!E41 -> -0.93437324 | C4: 2 | D4: 0.015151515 | E4: -2.1661068
B5: =LNs!E54 -> -0.75341749 | C5: 3 | D5: 0.025252525 | E5: -1.9556614
B6: =LNs!E62 -> -0.73775759 | C6: 4 | D6: 0.035353535 | E6: -1.8073542
B7: =LNs!E31 -> -0.73768649 | C7: 5 | D7: 0.045454545 | E7: -1.6906216
B8: =LNs!E66 -> -0.68521473 | C8: 6 | D8: 0.055555556 | E8: -1.5932188
B9: =LNs!E35 -> -0.66232704 | C9: 7 | D9: 0.065656566 | E9: -1.5089439
B10: =LNs!E38 -> -0.64513065 | C10: 8 | D10: 0.075757576 | E10: -1.4342002
B11: =LNs!E49 -> -0.63319855 | C11: 9 | D11: 0.085858586 | E11: -1.366707
B12: =LNs!E33 -> -0.62397193 | C12: 10 | D12: 0.095959596 | E12: -1.3049226
B13: =LNs!E72 -> -0.61476123 | C13: 11 | D13: 0.10606061 | E13: -1.2477539
B14: =LNs!E70 -> -0.55090484 | C14: 12 | D14: 0.11616162 | E14: -1.1943957
B15: =LNs!E37 -> -0.54473752 | C15: 13 | D15: 0.12626263 | E15: -1.1442373
B16: =LNs!E30 -> -0.53002543 | C16: 14 | D16: 0.13636364 | E16: -1.0968036
B17: =LNs!E40 -> -0.52445982 | C17: 15 | D17: 0.14646465 | E17: -1.0517173
B18: =LNs!E36 -> -0.51677998 | C18: 16 | D18: 0.15656566 | E18: -1.0086734
B19: =LNs!E61 -> -0.51078896 | C19: 17 | D19: 0.16666667 | E19: -0.96742157
B20: =LNs!E42 -> -0.48187542 | C20: 18 | D20: 0.17676768 | E20: -0.92775369
B21: =LNs!E65 -> -0.47278509 | C21: 19 | D21: 0.18686869 | E21: -0.88949451
B22: =LNs!E71 -> -0.46540144 | C22: 20 | D22: 0.1969697 | E22: -0.85249503
B23: =LNs!E53 -> -0.46482029 | C23: 21 | D23: 0.20707071 | E23: -0.81662736
B24: =LNs!E69 -> -0.43330455 | C24: 22 | D24: 0.21717172 | E24: -0.78178075
B25: =LNs!E4 -> -0.41171963 | C25: 23 | D25: 0.22727273 | E25: -0.74785859
B26: =LNs!E63 -> -0.40963881 | C26: 24 | D26: 0.23737374 | E26: -0.71477599
B27: =LNs!E26 -> -0.39014161 | C27: 25 | D27: 0.24747475 | E27: -0.68245784
B28: =LNs!E28 -> -0.38403293 | C28: 26 | D28: 0.25757576 | E28: -0.65083731
B29: =LNs!E60 -> -0.37110861 | C29: 27 | D29: 0.26767677 | E29: -0.61985457
B30: =LNs!E21 -> -0.36318034 | C30: 28 | D30: 0.27777778 | E30: -0.5894558
B31: =LNs!E44 -> -0.36293449 | C31: 29 | D31: 0.28787879 | E31: -0.55959227
B32: =LNs!E34 -> -0.32942115 | C32: 30 | D32: 0.2979798 | E32: -0.53021973
B33: =LNs!E32 -> -0.29736345 | C33: 31 | D33: 0.30808081 | E33: -0.50129771
B34: =LNs!E73 -> -0.28524371 | C34: 32 | D34: 0.31818182 | E34: -0.47278912
B35: =LNs!E45 -> -0.28415098 | C35: 33 | D35: 0.32828283 | E35: -0.44465976
B36: =LNs!E56 -> -0.27808956 | C36: 34 | D36: 0.33838384 | E36: -0.41687796
B37: =LNs!E19 -> -0.25917496 | C37: 35 | D37: 0.34848485 | E37: -0.3894143
B38: =LNs!E48 -> -0.2535525 | C38: 36 | D38: 0.35858586 | E38: -0.3622413
B39: =LNs!E58 -> -0.24565121 | C39: 37 | D39: 0.36868687 | E39: -0.33533322
B40: =LNs!E68 -> -0.23010019 | C40: 38 | D40: 0.37878788 | E40: -0.30866581
B41: =LNs!E94 -> -0.2081047 | C41: 39 | D41: 0.38888889 | E41: -0.28221615
...

Sheet Dec 5 Test
B2: Dec 5 Sorted | C2: Rank | D2: Rank Proportion | E2: Rank-Based Z Scores
B3: =LNs!F41 -> -1.0282312 | C3: 1 | D3: 0.0050505051 | E3: -2.5723521
B4: =LNs!F29 -> -0.9176066 | C4: 2 | D4: 0.015151515 | E4: -2.1661068
B5: =LNs!F62 -> -0.73198989 | C5: 3 | D5: 0.025252525 | E5: -1.9556614
B6: =LNs!F54 -> -0.73136216 | C6: 4 | D6: 0.035353535 | E6: -1.8073542
B7: =LNs!F31 -> -0.69020551 | C7: 5 | D7: 0.045454545 | E7: -1.6906216
B8: =LNs!F49 -> -0.65950933 | C8: 6 | D8: 0.055555556 | E8: -1.5932188
B9: =LNs!F40 -> -0.64786793 | C9: 7 | D9: 0.065656566 | E9: -1.5089439
B10: =LNs!F38 -> -0.63464811 | C10: 8 | D10: 0.075757576 | E10: -1.4342002
B11: =LNs!F72 -> -0.63353766 | C11: 9 | D11: 0.085858586 | E11: -1.366707
B12: =LNs!F66 -> -0.61085224 | C12: 10 | D12: 0.095959596 | E12: -1.3049226
B13: =LNs!F35 -> -0.59997929 | C13: 11 | D13: 0.10606061 | E13: -1.2477539
B14: =LNs!F33 -> -0.58998067 | C14: 12 | D14: 0.11616162 | E14: -1.1943957
B15: =LNs!F4 -> -0.55567481 | C15: 13 | D15: 0.12626263 | E15: -1.1442373
B16: =LNs!F42 -> -0.54316288 | C16: 14 | D16: 0.13636364 | E16: -1.0968036
B17: =LNs!F70 -> -0.5394103 | C17: 15 | D17: 0.14646465 | E17: -1.0517173
B18: =LNs!F30 -> -0.53329621 | C18: 16 | D18: 0.15656566 | E18: -1.0086734
B19: =LNs!F36 -> -0.52156138 | C19: 17 | D19: 0.16666667 | E19: -0.96742157
B20: =LNs!F65 -> -0.51330703 | C20: 18 | D20: 0.17676768 | E20: -0.92775369
B21: =LNs!F44 -> -0.49856114 | C21: 19 | D21: 0.18686869 | E21: -0.88949451
B22: =LNs!F28 -> -0.49757382 | C22: 20 | D22: 0.1969697 | E22: -0.85249503
B23: =LNs!F53 -> -0.46425379 | C23: 21 | D23: 0.20707071 | E23: -0.81662736
B24: =LNs!F19 -> -0.43561148 | C24: 22 | D24: 0.21717172 | E24: -0.78178075
B25: =LNs!F63 -> -0.43180806 | C25: 23 | D25: 0.22727273 | E25: -0.74785859
B26: =LNs!F26 -> -0.41539424 | C26: 24 | D26: 0.23737374 | E26: -0.71477599
B27: =LNs!F71 -> -0.40821037 | C27: 25 | D27: 0.24747475 | E27: -0.68245784
B28: =LNs!F21 -> -0.40153185 | C28: 26 | D28: 0.25757576 | E28: -0.65083731
B29: =LNs!F69 -> -0.39734516 | C29: 27 | D29: 0.26767677 | E29: -0.61985457
B30: =LNs!F61 -> -0.39139802 | C30: 28 | D30: 0.27777778 | E30: -0.5894558
B31: =LNs!F37 -> -0.387775 | C31: 29 | D31: 0.28787879 | E31: -0.55959227
B32: =LNs!F45 -> -0.35601088 | C32: 30 | D32: 0.2979798 | E32: -0.53021973
B33: =LNs!F60 -> -0.35385464 | C33: 31 | D33: 0.30808081 | E33: -0.50129771
B34: =LNs!F73 -> -0.33017073 | C34: 32 | D34: 0.31818182 | E34: -0.47278912
B35: =LNs!F48 -> -0.29926624 | C35: 33 | D35: 0.32828283 | E35: -0.44465976
B36: =LNs!F56 -> -0.27864569 | C36: 34 | D36: 0.33838384 | E36: -0.41687796
B37: =LNs!F58 -> -0.25709209 | C37: 35 | D37: 0.34848485 | E37: -0.3894143
B38: =LNs!F94 -> -0.25371488 | C38: 36 | D38: 0.35858586 | E38: -0.3622413
B39: =LNs!F46 -> -0.21804408 | C39: 37 | D39: 0.36868687 | E39: -0.33533322
B40: =LNs!F32 -> -0.2137082 | C40: 38 | D40: 0.37878788 | E40: -0.30866581
B41: =LNs!F68 -> -0.21271809 | C41: 39 | D41: 0.38888889 | E41: -0.28221615
...

Sheet Dec 6 Test
B2: Dec 6 Sorted | C2: Rank | D2: Rank Proportion | E2: Rank-Based Z Scores
B3: =LNs!G41 -> -1.1267186 | C3: 1 | D3: 0.0050505051 | E3: -2.5723521
B4: =LNs!G29 -> -0.94960453 | C4: 2 | D4: 0.015151515 | E4: -2.1661068
B5: =LNs!G40 -> -0.77708982 | C5: 3 | D5: 0.025252525 | E5: -1.9556614
B6: =LNs!G54 -> -0.7170506 | C6: 4 | D6: 0.035353535 | E6: -1.8073542
B7: =LNs!G38 -> -0.71696253 | C7: 5 | D7: 0.045454545 | E7: -1.6906216
B8: =LNs!G31 -> -0.69892786 | C8: 6 | D8: 0.055555556 | E8: -1.5932188
B9: =LNs!G35 -> -0.69873677 | C9: 7 | D9: 0.065656566 | E9: -1.5089439
B10: =LNs!G42 -> -0.66747359 | C10: 8 | D10: 0.075757576 | E10: -1.4342002
B11: =LNs!G62 -> -0.6652519 | C11: 9 | D11: 0.085858586 | E11: -1.366707
B12: =LNs!G36 -> -0.61697349 | C12: 10 | D12: 0.095959596 | E12: -1.3049226
B13: =LNs!G49 -> -0.61277161 | C13: 11 | D13: 0.10606061 | E13: -1.2477539
B14: =LNs!G66 -> -0.6039941 | C14: 12 | D14: 0.11616162 | E14: -1.1943957
B15: =LNs!G72 -> -0.59422173 | C15: 13 | D15: 0.12626263 | E15: -1.1442373
B16: =LNs!G30 -> -0.56619388 | C16: 14 | D16: 0.13636364 | E16: -1.0968036
B17: =LNs!G33 -> -0.55672821 | C17: 15 | D17: 0.14646465 | E17: -1.0517173
B18: =LNs!G70 -> -0.54307854 | C18: 16 | D18: 0.15656566 | E18: -1.0086734
B19: =LNs!G44 -> -0.52511557 | C19: 17 | D19: 0.16666667 | E19: -0.96742157
B20: =LNs!G37 -> -0.48648592 | C20: 18 | D20: 0.17676768 | E20: -0.92775369
B21: =LNs!G19 -> -0.481992 | C21: 19 | D21: 0.18686869 | E21: -0.88949451
B22: =LNs!G71 -> -0.46138012 | C22: 20 | D22: 0.1969697 | E22: -0.85249503
B23: =LNs!G4 -> -0.45466743 | C23: 21 | D23: 0.20707071 | E23: -0.81662736
B24: =LNs!G28 -> -0.4522313 | C24: 22 | D24: 0.21717172 | E24: -0.78178075
B25: =LNs!G53 -> -0.41472788 | C25: 23 | D25: 0.22727273 | E25: -0.74785859
B26: =LNs!G65 -> -0.40576765 | C26: 24 | D26: 0.23737374 | E26: -0.71477599
B27: =LNs!G69 -> -0.39864492 | C27: 25 | D27: 0.24747475 | E27: -0.68245784
B28: =LNs!G21 -> -0.39523313 | C28: 26 | D28: 0.25757576 | E28: -0.65083731
B29: =LNs!G45 -> -0.3933908 | C29: 27 | D29: 0.26767677 | E29: -0.61985457
B30: =LNs!G26 -> -0.36198617 | C30: 28 | D30: 0.27777778 | E30: -0.5894558
B31: =LNs!G63 -> -0.35088886 | C31: 29 | D31: 0.28787879 | E31: -0.55959227
B32: =LNs!G73 -> -0.34811738 | C32: 30 | D32: 0.2979798 | E32: -0.53021973
B33: =LNs!G94 -> -0.34173566 | C33: 31 | D33: 0.30808081 | E33: -0.50129771
B34: =LNs!G56 -> -0.34066381 | C34: 32 | D34: 0.31818182 | E34: -0.47278912
B35: =LNs!G46 -> -0.32241707 | C35: 33 | D35: 0.32828283 | E35: -0.44465976
B36: =LNs!G60 -> -0.31198979 | C36: 34 | D36: 0.33838384 | E36: -0.41687796
B37: =LNs!G61 -> -0.29831979 | C37: 35 | D37: 0.34848485 | E37: -0.3894143
B38: =LNs!G82 -> -0.2867545 | C38: 36 | D38: 0.35858586 | E38: -0.3622413
B39: =LNs!G34 -> -0.28188557 | C39: 37 | D39: 0.36868687 | E39: -0.33533322
B40: =LNs!G32 -> -0.25290455 | C40: 38 | D40: 0.37878788 | E40: -0.30866581
B41: =LNs!G83 -> -0.24952089 | C41: 39 | D41: 0.38888889 | E41: -0.28221615
...

Sheet Dec 7 Test
B2: Dec 7 Sorted | C2: Rank | D2: Rank Proportion | E2: Rank-Based Z Scores
B3: =LNs!H41 -> -1.1371525 | C3: 1 | D3: 0.0050505051 | E3: -2.5723521
B4: =LNs!H29 -> -0.90849619 | C4: 2 | D4: 0.015151515 | E4: -2.1661068
B5: =LNs!H31 -> -0.79108862 | C5: 3 | D5: 0.025252525 | E5: -1.9556614
B6: =LNs!H42 -> -0.78664061 | C6: 4 | D6: 0.035353535 | E6: -1.8073542
B7: =LNs!H38 -> -0.77872903 | C7: 5 | D7: 0.045454545 | E7: -1.6906216
B8: =LNs!H54 -> -0.74640873 | C8: 6 | D8: 0.055555556 | E8: -1.5932188
B9: =LNs!H35 -> -0.67401929 | C9: 7 | D9: 0.065656566 | E9: -1.5089439
B10: =LNs!H40 -> -0.64814322 | C10: 8 | D10: 0.075757576 | E10: -1.4342002
B11: =LNs!H70 -> -0.64320149 | C11: 9 | D11: 0.085858586 | E11: -1.366707
B12: =LNs!H49 -> -0.64062115 | C12: 10 | D12: 0.095959596 | E12: -1.3049226
B13: =LNs!H62 -> -0.61444691 | C13: 11 | D13: 0.10606061 | E13: -1.2477539
B14: =LNs!H36 -> -0.59272464 | C14: 12 | D14: 0.11616162 | E14: -1.1943957
B15: =LNs!H30 -> -0.58412956 | C15: 13 | D15: 0.12626263 | E15: -1.1442373
B16: =LNs!H72 -> -0.56891565 | C16: 14 | D16: 0.13636364 | E16: -1.0968036
B17: =LNs!H37 -> -0.56360072 | C17: 15 | D17: 0.14646465 | E17: -1.0517173
B18: =LNs!H44 -> -0.54462546 | C18: 16 | D18: 0.15656566 | E18: -1.0086734
B19: =LNs!H4 -> -0.52724468 | C19: 17 | D19: 0.16666667 | E19: -0.96742157
B20: =LNs!H66 -> -0.52247657 | C20: 18 | D20: 0.17676768 | E20: -0.92775369
B21: =LNs!H33 -> -0.50586628 | C21: 19 | D21: 0.18686869 | E21: -0.88949451
B22: =LNs!H69 -> -0.49228196 | C22: 20 | D22: 0.1969697 | E22: -0.85249503
B23: =LNs!H53 -> -0.48935119 | C23: 21 | D23: 0.20707071 | E23: -0.81662736
B24: =LNs!H94 -> -0.48930226 | C24: 22 | D24: 0.21717172 | E24: -0.78178075
B25: =LNs!H28 -> -0.44926497 | C25: 23 | D25: 0.22727273 | E25: -0.74785859
B26: =LNs!H71 -> -0.43121993 | C26: 24 | D26: 0.23737374 | E26: -0.71477599
B27: =LNs!H45 -> -0.40585919 | C27: 25 | D27: 0.24747475 | E27: -0.68245784
B28: =LNs!H19 -> -0.40272337 | C28: 26 | D28: 0.25757576 | E28: -0.65083731
B29: =LNs!H26 -> -0.39697922 | C29: 27 | D29: 0.26767677 | E29: -0.61985457
B30: =LNs!H73 -> -0.3925864 | C30: 28 | D30: 0.27777778 | E30: -0.5894558
B31: =LNs!H21 -> -0.37260109 | C31: 29 | D31: 0.28787879 | E31: -0.55959227
B32: =LNs!H56 -> -0.37093326 | C32: 30 | D32: 0.2979798 | E32: -0.53021973
B33: =LNs!H63 -> -0.33659084 | C33: 31 | D33: 0.30808081 | E33: -0.50129771
B34: =LNs!H82 -> -0.33422456 | C34: 32 | D34: 0.31818182 | E34: -0.47278912
B35: =LNs!H61 -> -0.32670707 | C35: 33 | D35: 0.32828283 | E35: -0.44465976
B36: =LNs!H48 -> -0.32568028 | C36: 34 | D36: 0.33838384 | E36: -0.41687796
B37: =LNs!H60 -> -0.31896636 | C37: 35 | D37: 0.34848485 | E37: -0.3894143
B38: =LNs!H65 -> -0.3060538 | C38: 36 | D38: 0.35858586 | E38: -0.3622413
B39: =LNs!H32 -> -0.30260622 | C39: 37 | D39: 0.36868687 | E39: -0.33533322
B40: =LNs!H46 -> -0.27747435 | C40: 38 | D40: 0.37878788 | E40: -0.30866581
B41: =LNs!H83 -> -0.27492249 | C41: 39 | D41: 0.38888889 | E41: -0.28221615
...

Sheet Dec 8 Test
B2: Dec 8 Sorted | C2: Rank | D2: Rank Proportion | E2: Rank-Based Z Scores
B3: =LNs!I41 -> -1.1664041 | C3: 1 | D3: 0.0050505051 | E3: -2.5723521
B4: =LNs!I29 -> -0.86269546 | C4: 2 | D4: 0.015151515 | E4: -2.1661068
B5: =LNs!I40 -> -0.80533316 | C5: 3 | D5: 0.025252525 | E5: -1.9556614
B6: =LNs!I49 -> -0.78305657 | C6: 4 | D6: 0.035353535 | E6: -1.8073542
B7: =LNs!I31 -> -0.74470156 | C7: 5 | D7: 0.045454545 | E7: -1.6906216
B8: =LNs!I38 -> -0.73471112 | C8: 6 | D8: 0.055555556 | E8: -1.5932188
B9: =LNs!I35 -> -0.73273036 | C9: 7 | D9: 0.065656566 | E9: -1.5089439
B10: =LNs!I42 -> -0.72061088 | C10: 8 | D10: 0.075757576 | E10: -1.4342002
B11: =LNs!I54 -> -0.69054657 | C11: 9 | D11: 0.085858586 | E11: -1.366707
B12: =LNs!I44 -> -0.64899251 | C12: 10 | D12: 0.095959596 | E12: -1.3049226
B13: =LNs!I36 -> -0.60758986 | C13: 11 | D13: 0.10606061 | E13: -1.2477539
B14: =LNs!I94 -> -0.60625781 | C14: 12 | D14: 0.11616162 | E14: -1.1943957
B15: =LNs!I62 -> -0.60064457 | C15: 13 | D15: 0.12626263 | E15: -1.1442373
B16: =LNs!I72 -> -0.5771257 | C16: 14 | D16: 0.13636364 | E16: -1.0968036
B17: =LNs!I33 -> -0.56265766 | C17: 15 | D17: 0.14646465 | E17: -1.0517173
B18: =LNs!I4 -> -0.56057625 | C18: 16 | D18: 0.15656566 | E18: -1.0086734
B19: =LNs!I30 -> -0.55393669 | C19: 17 | D19: 0.16666667 | E19: -0.96742157
B20: =LNs!I45 -> -0.52982497 | C20: 18 | D20: 0.17676768 | E20: -0.92775369
B21: =LNs!I21 -> -0.52312428 | C21: 19 | D21: 0.18686869 | E21: -0.88949451
B22: =LNs!I70 -> -0.51550656 | C22: 20 | D22: 0.1969697 | E22: -0.85249503
B23: =LNs!I37 -> -0.51314331 | C23: 21 | D23: 0.20707071 | E23: -0.81662736
B24: =LNs!I28 -> -0.49586312 | C24: 22 | D24: 0.21717172 | E24: -0.78178075
B25: =LNs!I69 -> -0.4946308 | C25: 23 | D25: 0.22727273 | E25: -0.74785859
B26: =LNs!I26 -> -0.47835682 | C26: 24 | D26: 0.23737374 | E26: -0.71477599
B27: =LNs!I71 -> -0.45555807 | C27: 25 | D27: 0.24747475 | E27: -0.68245784
B28: =LNs!I53 -> -0.45128865 | C28: 26 | D28: 0.25757576 | E28: -0.65083731
B29: =LNs!I19 -> -0.44154368 | C29: 27 | D29: 0.26767677 | E29: -0.61985457
B30: =LNs!I46 -> -0.41199136 | C30: 28 | D30: 0.27777778 | E30: -0.5894558
B31: =LNs!I66 -> -0.40143623 | C31: 29 | D31: 0.28787879 | E31: -0.55959227
B32: =LNs!I48 -> -0.39336412 | C32: 30 | D32: 0.2979798 | E32: -0.53021973
B33: =LNs!I56 -> -0.32611526 | C33: 31 | D33: 0.30808081 | E33: -0.50129771
B34: =LNs!I73 -> -0.3145724 | C34: 32 | D34: 0.31818182 | E34: -0.47278912
B35: =LNs!I82 -> -0.31434506 | C35: 33 | D35: 0.32828283 | E35: -0.44465976
B36: =LNs!I58 -> -0.2829546 | C36: 34 | D36: 0.33838384 | E36: -0.41687796
B37: =LNs!I32 -> -0.28222234 | C37: 35 | D37: 0.34848485 | E37: -0.3894143
B38: =LNs!I55 -> -0.27660762 | C38: 36 | D38: 0.35858586 | E38: -0.3622413
B39: =LNs!I61 -> -0.27153842 | C39: 37 | D39: 0.36868687 | E39: -0.33533322
B40: =LNs!I60 -> -0.27106359 | C40: 38 | D40: 0.37878788 | E40: -0.30866581
B41: =LNs!I34 -> -0.27006222 | C41: 39 | D41: 0.38888889 | E41: -0.28221615
...

Sheet Dec 9 Test
B2: Dec 9 Sorted | C2: Rank | D2: Rank Proportion | E2: Rank-Based Z Scores
B3: =LNs!J41 -> -1.1557669 | C3: 1 | D3: 0.0050505051 | E3: -2.5723521
B4: =LNs!J29 -> -0.99062104 | C4: 2 | D4: 0.015151515 | E4: -2.1661068
B5: =LNs!J42 -> -0.84719387 | C5: 3 | D5: 0.025252525 | E5: -1.9556614
B6: =LNs!J38 -> -0.8053712 | C6: 4 | D6: 0.035353535 | E6: -1.8073542
B7: =LNs!J31 -> -0.78758094 | C7: 5 | D7: 0.045454545 | E7: -1.6906216
B8: =LNs!J44 -> -0.72929677 | C8: 6 | D8: 0.055555556 | E8: -1.5932188
B9: =LNs!J49 -> -0.72887799 | C9: 7 | D9: 0.065656566 | E9: -1.5089439
B10: =LNs!J94 -> -0.7222609 | C10: 8 | D10: 0.075757576 | E10: -1.4342002
B11: =LNs!J35 -> -0.71713664 | C11: 9 | D11: 0.085858586 | E11: -1.366707
B12: =LNs!J30 -> -0.70354909 | C12: 10 | D12: 0.095959596 | E12: -1.3049226
B13: =LNs!J36 -> -0.69070616 | C13: 11 | D13: 0.10606061 | E13: -1.2477539
B14: =LNs!J40 -> -0.68526632 | C14: 12 | D14: 0.11616162 | E14: -1.1943957
B15: =LNs!J54 -> -0.65109778 | C15: 13 | D15: 0.12626263 | E15: -1.1442373
B16: =LNs!J72 -> -0.64582857 | C16: 14 | D16: 0.13636364 | E16: -1.0968036
B17: =LNs!J70 -> -0.62324805 | C17: 15 | D17: 0.14646465 | E17: -1.0517173
B18: =LNs!J21 -> -0.60897516 | C18: 16 | D18: 0.15656566 | E18: -1.0086734
B19: =LNs!J28 -> -0.60641184 | C19: 17 | D19: 0.16666667 | E19: -0.96742157
B20: =LNs!J45 -> -0.60493669 | C20: 18 | D20: 0.17676768 | E20: -0.92775369
B21: =LNs!J4 -> -0.56299474 | C21: 19 | D21: 0.18686869 | E21: -0.88949451
B22: =LNs!J37 -> -0.5599546 | C22: 20 | D22: 0.1969697 | E22: -0.85249503
B23: =LNs!J33 -> -0.53516613 | C23: 21 | D23: 0.20707071 | E23: -0.81662736
B24: =LNs!J62 -> -0.52680088 | C24: 22 | D24: 0.21717172 | E24: -0.78178075
B25: =LNs!J71 -> -0.51508635 | C25: 23 | D25: 0.22727273 | E25: -0.74785859
B26: =LNs!J26 -> -0.49347043 | C26: 24 | D26: 0.23737374 | E26: -0.71477599
B27: =LNs!J48 -> -0.46894499 | C27: 25 | D27: 0.24747475 | E27: -0.68245784
B28: =LNs!J69 -> -0.46318692 | C28: 26 | D28: 0.25757576 | E28: -0.65083731
B29: =LNs!J53 -> -0.4497807 | C29: 27 | D29: 0.26767677 | E29: -0.61985457
B30: =LNs!J46 -> -0.44386971 | C30: 28 | D30: 0.27777778 | E30: -0.5894558
B31: =LNs!J56 -> -0.42139024 | C31: 29 | D31: 0.28787879 | E31: -0.55959227
B32: =LNs!J19 -> -0.40027013 | C32: 30 | D32: 0.2979798 | E32: -0.53021973
B33: =LNs!J73 -> -0.36833552 | C33: 31 | D33: 0.30808081 | E33: -0.50129771
B34: =LNs!J83 -> -0.33962681 | C34: 32 | D34: 0.31818182 | E34: -0.47278912
B35: =LNs!J66 -> -0.3357441 | C35: 33 | D35: 0.32828283 | E35: -0.44465976
B36: =LNs!J55 -> -0.3242202 | C36: 34 | D36: 0.33838384 | E36: -0.41687796
B37: =LNs!J81 -> -0.31575513 | C37: 35 | D37: 0.34848485 | E37: -0.3894143
B38: =LNs!J90 -> -0.31240519 | C38: 36 | D38: 0.35858586 | E38: -0.3622413
B39: =LNs!J32 -> -0.31142847 | C39: 37 | D39: 0.36868687 | E39: -0.33533322
B40: =LNs!J82 -> -0.30907597 | C40: 38 | D40: 0.37878788 | E40: -0.30866581
B41: =LNs!J60 -> -0.29696233 | C41: 39 | D41: 0.38888889 | E41: -0.28221615
...

Sheet Hi 10 Test
B2: Hi 10 Sorted | C2: Rank | D2: Rank Proportion | E2: Rank-Based Z Scores
B3: =LNs!K41 -> -1.1073332 | C3: 1 | D3: 0.0050505051 | E3: -2.5723521
B4: =LNs!K21 -> -0.90500466 | C4: 2 | D4: 0.015151515 | E4: -2.1661068
B5: =LNs!K42 -> -0.88799243 | C5: 3 | D5: 0.025252525 | E5: -1.9556614
B6: =LNs!K94 -> -0.87438373 | C6: 4 | D6: 0.035353535 | E6: -1.8073542
B7: =LNs!K29 -> -0.76210291 | C7: 5 | D7: 0.045454545 | E7: -1.6906216
B8: =LNs!K72 -> -0.66741511 | C8: 6 | D8: 0.055555556 | E8: -1.5932188
B9: =LNs!K31 -> -0.66442757 | C9: 7 | D9: 0.065656566 | E9: -1.5089439
B10: =LNs!K4 -> -0.65645466 | C10: 8 | D10: 0.075757576 | E10: -1.4342002
B11: =LNs!K38 -> -0.65049774 | C11: 9 | D11: 0.085858586 | E11: -1.366707
B12: =LNs!K44 -> -0.64612811 | C12: 10 | D12: 0.095959596 | E12: -1.3049226
B13: =LNs!K49 -> -0.64172999 | C13: 11 | D13: 0.10606061 | E13: -1.2477539
B14: =LNs!K30 -> -0.62971802 | C14: 12 | D14: 0.11616162 | E14: -1.1943957
B15: =LNs!K26 -> -0.59286755 | C15: 13 | D15: 0.12626263 | E15: -1.1442373
B16: =LNs!K40 -> -0.58578986 | C16: 14 | D16: 0.13636364 | E16: -1.0968036
B17: =LNs!K70 -> -0.5735702 | C17: 15 | D17: 0.14646465 | E17: -1.0517173
B18: =LNs!K22 -> -0.55532799 | C18: 16 | D18: 0.15656566 | E18: -1.0086734
B19: =LNs!K20 -> -0.54911957 | C19: 17 | D19: 0.16666667 | E19: -0.96742157
B20: =LNs!K35 -> -0.53997298 | C20: 18 | D20: 0.17676768 | E20: -0.92775369
B21: =LNs!K45 -> -0.53169692 | C21: 19 | D21: 0.18686869 | E21: -0.88949451
B22: =LNs!K28 -> -0.53122563 | C22: 20 | D22: 0.1969697 | E22: -0.85249503
B23: =LNs!K54 -> -0.51802481 | C23: 21 | D23: 0.20707071 | E23: -0.81662736
B24: =LNs!K83 -> -0.51787709 | C24: 22 | D24: 0.21717172 | E24: -0.78178075
B25: =LNs!K36 -> -0.50139853 | C25: 23 | D25: 0.22727273 | E25: -0.74785859
B26: =LNs!K69 -> -0.49539857 | C26: 24 | D26: 0.23737374 | E26: -0.71477599
B27: =LNs!K82 -> -0.48482168 | C27: 25 | D27: 0.24747475 | E27: -0.68245784
B28: =LNs!K71 -> -0.46919915 | C28: 26 | D28: 0.25757576 | E28: -0.65083731
B29: =LNs!K48 -> -0.44879806 | C29: 27 | D29: 0.26767677 | E29: -0.61985457
B30: =LNs!K46 -> -0.43272942 | C30: 28 | D30: 0.27777778 | E30: -0.5894558
B31: =LNs!K62 -> -0.41707423 | C31: 29 | D31: 0.28787879 | E31: -0.55959227
B32: =LNs!K90 -> -0.41298531 | C32: 30 | D32: 0.2979798 | E32: -0.53021973
B33: =LNs!K37 -> -0.40416945 | C33: 31 | D33: 0.30808081 | E33: -0.50129771
B34: =LNs!K24 -> -0.40345513 | C34: 32 | D34: 0.31818182 | E34: -0.47278912
B35: =LNs!K81 -> -0.39279521 | C35: 33 | D35: 0.32828283 | E35: -0.44465976
B36: =LNs!K18 -> -0.38210704 | C36: 34 | D36: 0.33838384 | E36: -0.41687796
B37: =LNs!K19 -> -0.37869709 | C37: 35 | D37: 0.34848485 | E37: -0.3894143
B38: =LNs!K56 -> -0.34149222 | C38: 36 | D38: 0.35858586 | E38: -0.3622413
B39: =LNs!K53 -> -0.3394948 | C39: 37 | D39: 0.36868687 | E39: -0.33533322
B40: =LNs!K91 -> -0.33483797 | C40: 38 | D40: 0.37878788 | E40: -0.30866581
B41: =LNs!K33 -> -0.32884857 | C41: 39 | D41: 0.38888889 | E41: -0.28221615
...
