Workbook

Sheet README
A1: This spreadsheet was made by Ender Dempsey under the mentorship of Andrey Sarantsev, Ph.D.
A3: The SDs by Year for Deciles sheet is the data that finds the standard deviations of the data from the Kenneth R French Observatory titled "Portfolios Formed on BE-ME [Daily]"
A4: The LNs sheet is the natural logarithms of all the values in the SDs by Year for Deciles sheet. This also includes a line graph of all the standard deviations for each decile for each year.
A5: The Correlation Matrix was done using the data from the LNs sheet.
A6: For all of the other sheets, I took the corresponding logarithms for the titular decile for each year and put them in the first column. These logarithms were soreted from low to high. Since we are testing for normality, the next columns were the ranking of the sorted logarithms, their ranking proportion, and their z-score. From this data, I made a Quantile-Quantile plot and added a linear fit line. Since the data is linear, it is log-normally distributed.

Sheet SDs by Year For Deciles
A1: Standard Deviations by Year for Each Decile
A3: Year | B3: Lo 10 | C3: Dec 2 | D3: Dec 3 | E3: Dec 4 | F3: Dec 5 | G3: Dec 6 | H3: Dec 7 | I3: Dec 8 | J3: Dec 9 | K3: Hi 10
A4: 1927 | B4: 0.706514 | C4: 0.561133 | D4: 0.65985 | E4: 0.470897 | F4: 0.51548 | G4: 0.511574 | H4: 0.623786 | I4: 0.661616 | J4: 0.873932 | K4: 1.21655
A5: 1928 | B5: 1.05185 | C5: 0.9432 | D5: 0.751112 | E5: 0.81472 | F5: 0.888513 | G5: 0.719811 | H5: 0.656007 | I5: 0.846974 | J5: 1.19958 | K5: 1.31902
A6: 1929 | B6: 2.26169 | C6: 2.02244 | D6: 2.274 | E6: 1.81066 | F6: 1.65583 | G6: 1.76006 | H6: 1.62996 | I6: 1.53862 | J6: 1.73647 | K6: 2.08401
A7: 1930 | B7: 1.76302 | C7: 1.57272 | D7: 1.47631 | E7: 1.25769 | F7: 1.12725 | G7: 1.38438 | H7: 1.13696 | I7: 1.35471 | J7: 1.64545 | K7: 1.97038
A8: 1931 | B8: 2.04984 | C8: 1.85471 | D8: 1.76843 | E8: 2.23621 | F8: 2.20611 | G8: 2.52325 | H8: 2.56792 | I8: 2.5985 | J8: 2.95711 | K8: 2.83968
A9: 1932 | B9: 2.86846 | C9: 2.43419 | D9: 2.45828 | E9: 3.37875 | F9: 3.0886 | G9: 3.87484 | H9: 3.70232 | I9: 3.64989 | J9: 3.44124 | K9: 3.74819
A10: 1933 | B10: 2.44832 | C10: 2.18351 | D10: 2.3168 | E10: 3.25568 | F10: 3.15554 | G10: 3.31181 | H10: 3.62665 | I10: 3.83886 | J10: 3.94159 | K10: 4.34259
A11: 1934 | B11: 1.26624 | C11: 1.28651 | D11: 1.22189 | E11: 1.25065 | F11: 1.5464 | G11: 1.76423 | H11: 2.01841 | I11: 2.24879 | J11: 2.49294 | K11: 2.71309
A12: 1935 | B12: 0.846514 | C12: 0.995536 | D12: 0.937612 | E12: 0.866035 | F12: 0.926196 | G12: 1.11702 | H12: 1.47799 | I12: 1.82042 | J12: 2.28445 | K12: 2.39514
A13: 1936 | B13: 0.818106 | C13: 0.89482 | D13: 0.804272 | E13: 0.874409 | F13: 0.747289 | G13: 1.07547 | H13: 1.16023 | I13: 1.52801 | J13: 1.58748 | K13: 2.02959
A14: 1937 | B14: 1.67658 | C14: 1.59332 | D14: 1.6314 | E14: 1.71909 | F14: 1.53256 | G14: 1.38065 | H14: 1.70576 | I14: 2.1822 | J14: 2.17894 | K14: 3.14075
A15: 1938 | B15: 1.6288 | C15: 1.85658 | D15: 1.56588 | E15: 1.78596 | F15: 1.72406 | G15: 1.50208 | H15: 1.92721 | I15: 2.14955 | J15: 2.55428 | K15: 3.48771
... A102: 2025 | B102: 1.49115 | C102: 1.25508 | D102: 1.27404 | E102: 1.17238 | F102: 1.11763 | G102: 1.10615 | H102: 1.06383 | I102: 1.19841 | J102: 1.37254 | K102: 1.54579

Sheet Correlation Matrix
B1: Lo 10 | C1: Dec 2 | D1: Dec 3 | E1: Dec 4 | F1: Dec 5 | G1: Dec 6 | H1: Dec 7 | I1: Dec 8 | J1: Dec 9 | K1: Hi 10
A2: Lo 10 | B2: 1
A3: Dec 2 | B3: 0.94104924 | C3: 1
A4: Dec 3 | B4: 0.95524573 | C4: 0.97185812 | D4: 1
A5: Dec 4 | B5: 0.92013571 | C5: 0.96512465 | D5: 0.95640991 | E5: 1
A6: Dec 5 | B6: 0.90819592 | C6: 0.94417659 | D6: 0.94717912 | E6: 0.96299435 | F6: 1
A7: Dec 6 | B7: 0.85790635 | C7: 0.90407481 | D7: 0.90715518 | E7: 0.94450759 | F7: 0.95534066 | G7: 1
A8: Dec 7 | B8: 0.79537286 | C8: 0.87140264 | D8: 0.87113371 | E8: 0.91293327 | F8: 0.93105578 | G8: 0.96254127 | H8: 1
A9: Dec 8 | B9: 0.76330211 | C9: 0.83656757 | D9: 0.8368474 | E9: 0.87763355 | F9: 0.89839759 | G9: 0.94550392 | H9: 0.96609923 | I9: 1
A10: Dec 9 | B10: 0.71761181 | C10: 0.80669909 | D10: 0.80125204 | E10: 0.84248406 | F10: 0.8689652 | G10: 0.91717498 | H10: 0.94861269 | I10: 0.97425854 | J10: 1
A11: Hi 10 | B11: 0.61487859 | C11: 0.71885685 | D11: 0.70345861 | E11: 0.76328163 | F11: 0.78055091 | G11: 0.83952037 | H11: 0.88913746 | I11: 0.92167268 | J11: 0.95748453 | K11: 1

Sheet lns
A3: ='SDs by Year For Deciles'!A3 -> Year | B3: ='SDs by Year For Deciles'!B3 -> Lo 10 | C3: ='SDs by Year For Deciles'!C3 -> Dec 2 | D3: ='SDs by Year For Deciles'!D3 -> Dec 3 | E3: ='SDs by Year For Deciles'!E3 -> Dec 4 | F3: ='SDs by Year For Deciles'!F3 -> Dec 5 | G3: ='SDs by Year For Deciles'!G3 -> Dec 6 | H3: ='SDs by Year For Deciles'!H3 -> Dec 7 | ... K3: ='SDs by Year For Deciles'!K3 -> Hi 10
A4: ='SDs by Year For Deciles'!A4 -> 1927 | B4: =LN('SDs by Year For Deciles'!B4) -> -0.34741226 | C4: =LN('SDs by Year For Deciles'!C4) -> -0.57779732 | D4: =LN('SDs by Year For Deciles'!D4) -> -0.41574274 | E4: =LN('SDs by Year For Deciles'!E4) -> -0.75311589 | F4: =LN('SDs by Year For Deciles'!F4) -> -0.66265677 | G4: =LN('SDs by Year For Deciles'!G4) -> -0.67026303 | H4: =LN('SDs by Year For Deciles'!H4) -> -0.47194792 | I4: =LN('SDs by Year For Deciles'!I4) -> -0.41306995 | ... K4: =LN('SDs by Year For Deciles'!K4) -> 0.19601898
A5: ='SDs by Year For Deciles'!A5 -> 1928 | B5: =LN('SDs by Year For Deciles'!B5) -> 0.050550519 | C5: =LN('SDs by Year For Deciles'!C5) -> -0.05847693 | D5: =LN('SDs by Year For Deciles'!D5) -> -0.2862005 | E5: =LN('SDs by Year For Deciles'!E5) -> -0.20491078 | F5: =LN('SDs by Year For Deciles'!F5) -> -0.118206 | G5: =LN('SDs by Year For Deciles'!G5) -> -0.3287666 | H5: =LN('SDs by Year For Deciles'!H5) -> -0.42158382 | I5: =LN('SDs by Year For Deciles'!I5) -> -0.16608528 | ... K5: =LN('SDs by Year For Deciles'!K5) -> 0.27688904
A6: ='SDs by Year For Deciles'!A6 -> 1929 | B6: =LN('SDs by Year For Deciles'!B6) -> 0.81611232 | C6: =LN('SDs by Year For Deciles'!C6) -> 0.7043047 | D6: =LN('SDs by Year For Deciles'!D6) -> 0.8215404 | E6: =LN('SDs by Year For Deciles'!E6) -> 0.59369142 | F6: =LN('SDs by Year For Deciles'!F6) -> 0.50430239 | G6: =LN('SDs by Year For Deciles'!G6) -> 0.5653479 | H6: =LN('SDs by Year For Deciles'!H6) -> 0.48855547 | I6: =LN('SDs by Year For Deciles'!I6) -> 0.43088591 | ... K6: =LN('SDs by Year For Deciles'!K6) -> 0.73429392
A7: ='SDs by Year For Deciles'!A7 -> 1930 | B7: =LN('SDs by Year For Deciles'!B7) -> 0.56702825 | C7: =LN('SDs by Year For Deciles'!C7) -> 0.4528066 | D7: =LN('SDs by Year For Deciles'!D7) -> 0.38954573 | E7: =LN('SDs by Year For Deciles'!E7) -> 0.22927671 | F7: =LN('SDs by Year For Deciles'!F7) -> 0.11978104 | G7: =LN('SDs by Year For Deciles'!G7) -> 0.32525239 | H7: =LN('SDs by Year For Deciles'!H7) -> 0.12835803 | I7: =LN('SDs by Year For Deciles'!I7) -> 0.30358741 | ... K7: =LN('SDs by Year For Deciles'!K7) -> 0.67822642
A8: ='SDs by Year For Deciles'!A8 -> 1931 | B8: =LN('SDs by Year For Deciles'!B8) -> 0.71776174 | C8: =LN('SDs by Year For Deciles'!C8) -> 0.61772835 | D8: =LN('SDs by Year For Deciles'!D8) -> 0.57009215 | E8: =LN('SDs by Year For Deciles'!E8) -> 0.80478247 | F8: =LN('SDs by Year For Deciles'!F8) -> 0.79123078 | G8: =LN('SDs by Year For Deciles'!G8) -> 0.92554775 | H8: =LN('SDs by Year For Deciles'!H8) -> 0.94309623 | I8: =LN('SDs by Year For Deciles'!I8) -> 0.95493436 | ... K8: =LN('SDs by Year For Deciles'!K8) -> 1.0436914
A9: ='SDs by Year For Deciles'!A9 -> 1932 | B9: =LN('SDs by Year For Deciles'!B9) -> 1.0537753 | C9: =LN('SDs by Year For Deciles'!C9) -> 0.88961405 | D9: =LN('SDs by Year For Deciles'!D9) -> 0.89946192 | E9: =LN('SDs by Year For Deciles'!E9) -> 1.2175058 | F9: =LN('SDs by Year For Deciles'!F9) -> 1.1277179 | G9: =LN('SDs by Year For Deciles'!G9) -> 1.3545044 | H9: =LN('SDs by Year For Deciles'!H9) -> 1.3089597 | I9: =LN('SDs by Year For Deciles'!I9) -> 1.294697 | ... K9: =LN('SDs by Year For Deciles'!K9) -> 1.3212731
A10: ='SDs by Year For Deciles'!A10 -> 1933 | B10: =LN('SDs by Year For Deciles'!B10) -> 0.89540208 | C10: =LN('SDs by Year For Deciles'!C10) -> 0.78093367 | D10: =LN('SDs by Year For Deciles'!D10) -> 0.84018692 | E10: =LN('SDs by Year For Deciles'!E10) -> 1.1804012 | F10: =LN('SDs by Year For Deciles'!F10) -> 1.1491596 | G10: =LN('SDs by Year For Deciles'!G10) -> 1.1974949 | H10: =LN('SDs by Year For Deciles'!H10) -> 1.2883094 | I10: =LN('SDs by Year For Deciles'!I10) -> 1.3451754 | ... K10: =LN('SDs by Year For Deciles'!K10) -> 1.4684709
A11: ='SDs by Year For Deciles'!A11 -> 1934 | B11: =LN('SDs by Year For Deciles'!B11) -> 0.23605188 | C11: =LN('SDs by Year For Deciles'!C11) -> 0.25193313 | D11: =LN('SDs by Year For Deciles'!D11) -> 0.20039884 | E11: =LN('SDs by Year For Deciles'!E11) -> 0.22366342 | F11: =LN('SDs by Year For Deciles'!F11) -> 0.43592965 | G11: =LN('SDs by Year For Deciles'!G11) -> 0.56771433 | H11: =LN('SDs by Year For Deciles'!H11) -> 0.70231007 | I11: =LN('SDs by Year For Deciles'!I11) -> 0.81039229 | ... K11: =LN('SDs by Year For Deciles'!K11) -> 0.99808821
A12: ='SDs by Year For Deciles'!A12 -> 1935 | B12: =LN('SDs by Year For Deciles'!B12) -> -0.16662854 | C12: =LN('SDs by Year For Deciles'!C12) -> -0.0044739934 | D12: =LN('SDs by Year For Deciles'!D12) -> -0.064419062 | E12: =LN('SDs by Year For Deciles'!E12) -> -0.14382996 | F12: =LN('SDs by Year For Deciles'!F12) -> -0.076669404 | G12: =LN('SDs by Year For Deciles'!G12) -> 0.11066443 | H12: =LN('SDs by Year For Deciles'!H12) -> 0.39068306 | I12: =LN('SDs by Year For Deciles'!I12) -> 0.59906724 | ... K12: =LN('SDs by Year For Deciles'!K12) -> 0.87344168
A13: ='SDs by Year For Deciles'!A13 -> 1936 | B13: =LN('SDs by Year For Deciles'!B13) -> -0.20076337 | C13: =LN('SDs by Year For Deciles'!C13) -> -0.1111327 | D13: =LN('SDs by Year For Deciles'!D13) -> -0.21781776 | E13: =LN('SDs by Year For Deciles'!E13) -> -0.13420705 | F13: =LN('SDs by Year For Deciles'!F13) -> -0.29130329 | G13: =LN('SDs by Year For Deciles'!G13) -> 0.072757775 | H13: =LN('SDs by Year For Deciles'!H13) -> 0.14861826 | I13: =LN('SDs by Year For Deciles'!I13) -> 0.42396624 | ... K13: =LN('SDs by Year For Deciles'!K13) -> 0.7078338
A14: ='SDs by Year For Deciles'!A14 -> 1937 | B14: =LN('SDs by Year For Deciles'!B14) -> 0.516756 | C14: =LN('SDs by Year For Deciles'!C14) -> 0.46581989 | D14: =LN('SDs by Year For Deciles'!D14) -> 0.48943854 | E14: =LN('SDs by Year For Deciles'!E14) -> 0.54179508 | F14: =LN('SDs by Year For Deciles'!F14) -> 0.42693954 | G14: =LN('SDs by Year For Deciles'!G14) -> 0.3225544 | H14: =LN('SDs by Year For Deciles'!H14) -> 0.53401076 | I14: =LN('SDs by Year For Deciles'!I14) -> 0.78033354 | ... K14: =LN('SDs by Year For Deciles'!K14) -> 1.1444616
A15: ='SDs by Year For Deciles'!A15 -> 1938 | B15: =LN('SDs by Year For Deciles'!B15) -> 0.48784355 | C15: =LN('SDs by Year For Deciles'!C15) -> 0.61873609 | D15: =LN('SDs by Year For Deciles'!D15) -> 0.44844797 | E15: =LN('SDs by Year For Deciles'!E15) -> 0.57995609 | F15: =LN('SDs by Year For Deciles'!F15) -> 0.54468197 | G15: =LN('SDs by Year For Deciles'!G15) -> 0.40685081 | H15: =LN('SDs by Year For Deciles'!H15) -> 0.65607336 | I15: =LN('SDs by Year For Deciles'!I15) -> 0.76525852 | ... K15: =LN('SDs by Year For Deciles'!K15) -> 1.2492454
... A102: ='SDs by Year For Deciles'!A102 -> 2025 | B102: =LN('SDs by Year For Deciles'!B102) -> 0.39954763 | C102: =LN('SDs by Year For Deciles'!C102) -> 0.22719932 | D102: =LN('SDs by Year For Deciles'!D102) -> 0.24219295 | E102: =LN('SDs by Year For Deciles'!E102) -> 0.15903587 | F102: =LN('SDs by Year For Deciles'!F102) -> 0.11121037 | G102: =LN('SDs by Year For Deciles'!G102) -> 0.10088552 | H102: =LN('SDs by Year For Deciles'!H102) -> 0.061875604 | I102: =LN('SDs by Year For Deciles'!I102) -> 0.18099568 | ... K102: =LN('SDs by Year For Deciles'!K102) -> 0.43553511

Sheet Lo 10 Test
B3: Ln of Lo 10 Sorted | C3: Rank | D3: Rank Proportion | E3: Rank-Based Z Scores
B4: =lns!B41 -> -0.93395076 | C4: 1 | D4: =(C4-0.5)/99 -> 0.0050505051 | E4: =NORMSINV(D4) -> -2.5723521
B5: =lns!B21 -> -0.83268975 | C5: 2 | D5: =(C5-0.5)/99 -> 0.015151515 | E5: =NORMSINV(D5) -> -2.1661068
B6: =lns!B94 -> -0.81990613 | C6: 3 | D6: =(C6-0.5)/99 -> 0.025252525 | E6: =NORMSINV(D6) -> -1.9556614
B7: =lns!B29 -> -0.79023975 | C7: 4 | D7: =(C7-0.5)/99 -> 0.035353535 | E7: =NORMSINV(D7) -> -1.8073542
B8: =lns!B42 -> -0.65638718 | C8: 5 | D8: =(C8-0.5)/99 -> 0.045454545 | E8: =NORMSINV(D8) -> -1.6906216
B9: =lns!B20 -> -0.62176277 | C9: 6 | D9: =(C9-0.5)/99 -> 0.055555556 | E9: =NORMSINV(D9) -> -1.5932188
B10: =lns!B26 -> -0.58976422 | C10: 7 | D10: =(C10-0.5)/99 -> 0.065656566 | E10: =NORMSINV(D10) -> -1.5089439
B11: =lns!B38 -> -0.56563562 | C11: 8 | D11: =(C11-0.5)/99 -> 0.075757576 | E11: =NORMSINV(D11) -> -1.4342002
B12: =lns!B28 -> -0.56291573 | C12: 9 | D12: =(C12-0.5)/99 -> 0.085858586 | E12: =NORMSINV(D12) -> -1.366707
B13: =lns!B30 -> -0.53616736 | C13: 10 | D13: =(C13-0.5)/99 -> 0.095959596 | E13: =NORMSINV(D13) -> -1.3049226
B14: =lns!B72 -> -0.52970947 | C14: 11 | D14: =(C14-0.5)/99 -> 0.10606061 | E14: =NORMSINV(D14) -> -1.2477539
B15: =lns!B40 -> -0.5257227 | C15: 12 | D15: =(C15-0.5)/99 -> 0.11616162 | E15: =NORMSINV(D15) -> -1.1943957
B16: =lns!B22 -> -0.50447251 | C16: 13 | D16: =(C16-0.5)/99 -> 0.12626263 | E16: =NORMSINV(D16) -> -1.1442373
B17: =lns!B31 -> -0.5002946 | C17: 14 | D17: =(C17-0.5)/99 -> 0.13636364 | E17: =NORMSINV(D17) -> -1.0968036
B18: =lns!B35 -> -0.49097888 | C18: 15 | D18: =(C18-0.5)/99 -> 0.14646465 | E18: =NORMSINV(D18) -> -1.0517173
B19: =lns!B82 -> -0.47136936 | C19: 16 | D19: =(C19-0.5)/99 -> 0.15656566 | E19: =NORMSINV(D19) -> -1.0086734
B20: =lns!B49 -> -0.44696546 | C20: 17 | D20: =(C20-0.5)/99 -> 0.16666667 | E20: =NORMSINV(D20) -> -0.96742157
B21: =lns!B36 -> -0.39252865 | C21: 18 | D21: =(C21-0.5)/99 -> 0.17676768 | E21: =NORMSINV(D21) -> -0.92775369
B22: =lns!B54 -> -0.38846051 | C22: 19 | D22: =(C22-0.5)/99 -> 0.18686869 | E22: =NORMSINV(D22) -> -0.88949451
B23: =lns!B83 -> -0.38266257 | C23: 20 | D23: =(C23-0.5)/99 -> 0.1969697 | E23: =NORMSINV(D23) -> -0.85249503
B24: =lns!B24 -> -0.36308832 | C24: 21 | D24: =(C24-0.5)/99 -> 0.20707071 | E24: =NORMSINV(D24) -> -0.81662736
B25: =lns!B44 -> -0.36291581 | C25: 22 | D25: =(C25-0.5)/99 -> 0.21717172 | E25: =NORMSINV(D25) -> -0.78178075
B26: =lns!B71 -> -0.34896191 | C26: 23 | D26: =(C26-0.5)/99 -> 0.22727273 | E26: =NORMSINV(D26) -> -0.74785859
B27: =lns!B81 -> -0.34795026 | C27: 24 | D27: =(C27-0.5)/99 -> 0.23737374 | E27: =NORMSINV(D27) -> -0.71477599
B28: =lns!B4 -> -0.34741226 | C28: 25 | D28: =(C28-0.5)/99 -> 0.24747475 | E28: =NORMSINV(D28) -> -0.68245784
B29: =lns!B19 -> -0.34436954 | C29: 26 | D29: =(C29-0.5)/99 -> 0.25757576 | E29: =NORMSINV(D29) -> -0.65083731
B30: =lns!B18 -> -0.33059375 | C30: 27 | D30: =(C30-0.5)/99 -> 0.26767677 | E30: =NORMSINV(D30) -> -0.61985457
B31: =lns!B90 -> -0.32143605 | C31: 28 | D31: =(C31-0.5)/99 -> 0.27777778 | E31: =NORMSINV(D31) -> -0.5894558
B32: =lns!B25 -> -0.32124575 | C32: 29 | D32: =(C32-0.5)/99 -> 0.28787879 | E32: =NORMSINV(D32) -> -0.55959227
B33: =lns!B48 -> -0.29266379 | C33: 30 | D33: =(C33-0.5)/99 -> 0.2979798 | E33: =NORMSINV(D33) -> -0.53021973
B34: =lns!B33 -> -0.27960809 | C34: 31 | D34: =(C34-0.5)/99 -> 0.30808081 | E34: =NORMSINV(D34) -> -0.50129771
B35: =lns!B56 -> -0.27787829 | C35: 32 | D35: =(C35-0.5)/99 -> 0.31818182 | E35: =NORMSINV(D35) -> -0.47278912
B36: =lns!B62 -> -0.27119736 | C36: 33 | D36: =(C36-0.5)/99 -> 0.32828283 | E36: =NORMSINV(D36) -> -0.44465976
B37: =lns!B53 -> -0.2651003 | C37: 34 | D37: =(C37-0.5)/99 -> 0.33838384 | E37: =NORMSINV(D37) -> -0.41687796
B38: =lns!B37 -> -0.25273587 | C38: 35 | D38: =(C38-0.5)/99 -> 0.34848485 | E38: =NORMSINV(D38) -> -0.3894143
B39: =lns!B70 -> -0.22194302 | C39: 36 | D39: =(C39-0.5)/99 -> 0.35858586 | E39: =NORMSINV(D39) -> -0.3622413
B40: =lns!B69 -> -0.21921129 | C40: 37 | D40: =(C40-0.5)/99 -> 0.36868687 | E40: =NORMSINV(D40) -> -0.33533322
B41: =lns!B46 -> -0.21276881 | C41: 38 | D41: =(C41-0.5)/99 -> 0.37878788 | E41: =NORMSINV(D41) -> -0.30866581
B42: =lns!B27 -> -0.20667245 | C42: 39 | D42: =(C42-0.5)/99 -> 0.38888889 | E42: =NORMSINV(D42) -> -0.28221615
...

Sheet Dec 2 Test
B3: Lns of Dec 2 Sorted | C3: Rank | D3: Rank Proportion | E3: Rank-Based Z Scores
B4: =lns!C41 -> -0.9923298 | C4: 1 | D4: =(C4-0.5)/99 -> 0.0050505051 | E4: =NORMSINV(D4) -> -2.5723521
B5: =lns!C42 -> -0.91039564 | C5: 2 | D5: =(C5-0.5)/99 -> 0.015151515 | E5: =NORMSINV(D5) -> -2.1661068
B6: =lns!C31 -> -0.88186998 | C6: 3 | D6: =(C6-0.5)/99 -> 0.025252525 | E6: =NORMSINV(D6) -> -1.9556614
B7: =lns!C29 -> -0.84751355 | C7: 4 | D7: =(C7-0.5)/99 -> 0.035353535 | E7: =NORMSINV(D7) -> -1.8073542
B8: =lns!C38 -> -0.82057836 | C8: 5 | D8: =(C8-0.5)/99 -> 0.045454545 | E8: =NORMSINV(D8) -> -1.6906216
B9: =lns!C44 -> -0.745852 | C9: 6 | D9: =(C9-0.5)/99 -> 0.055555556 | E9: =NORMSINV(D9) -> -1.5932188
B10: =lns!C21 -> -0.724351 | C10: 7 | D10: =(C10-0.5)/99 -> 0.065656566 | E10: =NORMSINV(D10) -> -1.5089439
B11: =lns!C30 -> -0.71635235 | C11: 8 | D11: =(C11-0.5)/99 -> 0.075757576 | E11: =NORMSINV(D11) -> -1.4342002
B12: =lns!C49 -> -0.61420847 | C12: 9 | D12: =(C12-0.5)/99 -> 0.085858586 | E12: =NORMSINV(D12) -> -1.366707
B13: =lns!C28 -> -0.61085224 | C13: 10 | D13: =(C13-0.5)/99 -> 0.095959596 | E13: =NORMSINV(D13) -> -1.3049226
B14: =lns!C72 -> -0.60740444 | C14: 11 | D14: =(C14-0.5)/99 -> 0.10606061 | E14: =NORMSINV(D14) -> -1.2477539
B15: =lns!C4 -> -0.57779732 | C15: 12 | D15: =(C15-0.5)/99 -> 0.11616162 | E15: =NORMSINV(D15) -> -1.1943957
B16: =lns!C94 -> -0.54844615 | C16: 13 | D16: =(C16-0.5)/99 -> 0.12626263 | E16: =NORMSINV(D16) -> -1.1442373
B17: =lns!C26 -> -0.53448327 | C17: 14 | D17: =(C17-0.5)/99 -> 0.13636364 | E17: =NORMSINV(D17) -> -1.0968036
B18: =lns!C70 -> -0.50109314 | C18: 15 | D18: =(C18-0.5)/99 -> 0.14646465 | E18: =NORMSINV(D18) -> -1.0517173
B19: =lns!C45 -> -0.49620634 | C19: 16 | D19: =(C19-0.5)/99 -> 0.15656566 | E19: =NORMSINV(D19) -> -1.0086734
B20: =lns!C36 -> -0.48745421 | C20: 17 | D20: =(C20-0.5)/99 -> 0.16666667 | E20: =NORMSINV(D20) -> -0.96742157
B21: =lns!C40 -> -0.4829365 | C21: 18 | D21: =(C21-0.5)/99 -> 0.17676768 | E21: =NORMSINV(D21) -> -0.92775369
B22: =lns!C35 -> -0.4672953 | C22: 19 | D22: =(C22-0.5)/99 -> 0.18686869 | E22: =NORMSINV(D22) -> -0.88949451
B23: =lns!C37 -> -0.46472956 | C23: 20 | D23: =(C23-0.5)/99 -> 0.1969697 | E23: =NORMSINV(D23) -> -0.85249503
B24: =lns!C71 -> -0.4523319 | C24: 21 | D24: =(C24-0.5)/99 -> 0.20707071 | E24: =NORMSINV(D24) -> -0.81662736
B25: =lns!C54 -> -0.43274638 | C25: 22 | D25: =(C25-0.5)/99 -> 0.21717172 | E25: =NORMSINV(D25) -> -0.78178075
B26: =lns!C69 -> -0.41479903 | C26: 23 | D26: =(C26-0.5)/99 -> 0.22727273 | E26: =NORMSINV(D26) -> -0.74785859
B27: =lns!C90 -> -0.41426017 | C27: 24 | D27: =(C27-0.5)/99 -> 0.23737374 | E27: =NORMSINV(D27) -> -0.71477599
B28: =lns!C18 -> -0.40000305 | C28: 25 | D28: =(C28-0.5)/99 -> 0.24747475 | E28: =NORMSINV(D28) -> -0.68245784
B29: =lns!C19 -> -0.39887437 | C29: 26 | D29: =(C29-0.5)/99 -> 0.25757576 | E29: =NORMSINV(D29) -> -0.65083731
B30: =lns!C20 -> -0.39324854 | C30: 27 | D30: =(C30-0.5)/99 -> 0.26767677 | E30: =NORMSINV(D30) -> -0.61985457
B31: =lns!C43 -> -0.39117766 | C31: 28 | D31: =(C31-0.5)/99 -> 0.27777778 | E31: =NORMSINV(D31) -> -0.5894558
B32: =lns!C48 -> -0.38657466 | C32: 29 | D32: =(C32-0.5)/99 -> 0.28787879 | E32: =NORMSINV(D32) -> -0.55959227
B33: =lns!C62 -> -0.37306133 | C33: 30 | D33: =(C33-0.5)/99 -> 0.2979798 | E33: =NORMSINV(D33) -> -0.53021973
B34: =lns!C53 -> -0.37148841 | C34: 31 | D34: =(C34-0.5)/99 -> 0.30808081 | E34: =NORMSINV(D34) -> -0.50129771
B35: =lns!C83 -> -0.35765113 | C35: 32 | D35: =(C35-0.5)/99 -> 0.31818182 | E35: =NORMSINV(D35) -> -0.47278912
B36: =lns!C82 -> -0.35597233 | C36: 33 | D36: =(C36-0.5)/99 -> 0.32828283 | E36: =NORMSINV(D36) -> -0.44465976
B37: =lns!C33 -> -0.34909375 | C37: 34 | D37: =(C37-0.5)/99 -> 0.33838384 | E37: =NORMSINV(D37) -> -0.41687796
B38: =lns!C22 -> -0.33726455 | C38: 35 | D38: =(C38-0.5)/99 -> 0.34848485 | E38: =NORMSINV(D38) -> -0.3894143
B39: =lns!C91 -> -0.32998433 | C39: 36 | D39: =(C39-0.5)/99 -> 0.35858586 | E39: =NORMSINV(D39) -> -0.3622413
B40: =lns!C32 -> -0.29207035 | C40: 37 | D40: =(C40-0.5)/99 -> 0.36868687 | E40: =NORMSINV(D40) -> -0.33533322
B41: =lns!C56 -> -0.27453159 | C41: 38 | D41: =(C41-0.5)/99 -> 0.37878788 | E41: =NORMSINV(D41) -> -0.30866581
B42: =lns!C81 -> -0.23112532 | C42: 39 | D42: =(C42-0.5)/99 -> 0.38888889 | E42: =NORMSINV(D42) -> -0.28221615
...

Sheet Dec 3 Test
B3: Lns of Dec 3 Sorted | C3: Rank | D3: Rank Proportion | E3: Rank-Based Z Scores
B4: =lns!D21 -> -1.095884 | C4: 1 | D4: =(C4-0.5)/99 -> 0.0050505051 | E4: =NORMSINV(D4) -> -2.5723521
B5: =lns!D41 -> -1.0421119 | C5: 2 | D5: =(C5-0.5)/99 -> 0.015151515 | E5: =NORMSINV(D5) -> -2.1661068
B6: =lns!D42 -> -0.93865905 | C6: 3 | D6: =(C6-0.5)/99 -> 0.025252525 | E6: =NORMSINV(D6) -> -1.9556614
B7: =lns!D94 -> -0.78467931 | C7: 4 | D7: =(C7-0.5)/99 -> 0.035353535 | E7: =NORMSINV(D7) -> -1.8073542
B8: =lns!D29 -> -0.74963923 | C8: 5 | D8: =(C8-0.5)/99 -> 0.045454545 | E8: =NORMSINV(D8) -> -1.6906216
B9: =lns!D31 -> -0.72365175 | C9: 6 | D9: =(C9-0.5)/99 -> 0.055555556 | E9: =NORMSINV(D9) -> -1.5932188
B10: =lns!D26 -> -0.66248995 | C10: 7 | D10: =(C10-0.5)/99 -> 0.065656566 | E10: =NORMSINV(D10) -> -1.5089439
B11: =lns!D40 -> -0.61253356 | C11: 8 | D11: =(C11-0.5)/99 -> 0.075757576 | E11: =NORMSINV(D11) -> -1.4342002
B12: =lns!D28 -> -0.59812068 | C12: 9 | D12: =(C12-0.5)/99 -> 0.085858586 | E12: =NORMSINV(D12) -> -1.366707
B13: =lns!D38 -> -0.59511888 | C13: 10 | D13: =(C13-0.5)/99 -> 0.095959596 | E13: =NORMSINV(D13) -> -1.3049226
B14: =lns!D49 -> -0.58964339 | C14: 11 | D14: =(C14-0.5)/99 -> 0.10606061 | E14: =NORMSINV(D14) -> -1.2477539
B15: =lns!D35 -> -0.56976739 | C15: 12 | D15: =(C15-0.5)/99 -> 0.11616162 | E15: =NORMSINV(D15) -> -1.1943957
B16: =lns!D30 -> -0.56595786 | C16: 13 | D16: =(C16-0.5)/99 -> 0.12626263 | E16: =NORMSINV(D16) -> -1.1442373
B17: =lns!D54 -> -0.5650548 | C17: 14 | D17: =(C17-0.5)/99 -> 0.13636364 | E17: =NORMSINV(D17) -> -1.0968036
B18: =lns!D72 -> -0.53757351 | C18: 15 | D18: =(C18-0.5)/99 -> 0.14646465 | E18: =NORMSINV(D18) -> -1.0517173
B19: =lns!D44 -> -0.53120011 | C19: 16 | D19: =(C19-0.5)/99 -> 0.15656566 | E19: =NORMSINV(D19) -> -1.0086734
B20: =lns!D20 -> -0.53012738 | C20: 17 | D20: =(C20-0.5)/99 -> 0.16666667 | E20: =NORMSINV(D20) -> -0.96742157
B21: =lns!D70 -> -0.52713626 | C21: 18 | D21: =(C21-0.5)/99 -> 0.17676768 | E21: =NORMSINV(D21) -> -0.92775369
B22: =lns!D22 -> -0.51748273 | C22: 19 | D22: =(C22-0.5)/99 -> 0.18686869 | E22: =NORMSINV(D22) -> -0.88949451
B23: =lns!D69 -> -0.51259886 | C23: 20 | D23: =(C23-0.5)/99 -> 0.1969697 | E23: =NORMSINV(D23) -> -0.85249503
B24: =lns!D36 -> -0.49651682 | C24: 21 | D24: =(C24-0.5)/99 -> 0.20707071 | E24: =NORMSINV(D24) -> -0.81662736
B25: =lns!D62 -> -0.4832445 | C25: 22 | D25: =(C25-0.5)/99 -> 0.21717172 | E25: =NORMSINV(D25) -> -0.78178075
B26: =lns!D71 -> -0.46752989 | C26: 23 | D26: =(C26-0.5)/99 -> 0.22727273 | E26: =NORMSINV(D26) -> -0.74785859
B27: =lns!D18 -> -0.42777207 | C27: 24 | D27: =(C27-0.5)/99 -> 0.23737374 | E27: =NORMSINV(D27) -> -0.71477599
B28: =lns!D53 -> -0.42246072 | C28: 25 | D28: =(C28-0.5)/99 -> 0.24747475 | E28: =NORMSINV(D28) -> -0.68245784
B29: =lns!D4 -> -0.41574274 | C29: 26 | D29: =(C29-0.5)/99 -> 0.25757576 | E29: =NORMSINV(D29) -> -0.65083731
B30: =lns!D19 -> -0.40490526 | C30: 27 | D30: =(C30-0.5)/99 -> 0.26767677 | E30: =NORMSINV(D30) -> -0.61985457
B31: =lns!D45 -> -0.39989117 | C31: 28 | D31: =(C31-0.5)/99 -> 0.27777778 | E31: =NORMSINV(D31) -> -0.5894558
B32: =lns!D83 -> -0.36865065 | C32: 29 | D32: =(C32-0.5)/99 -> 0.28787879 | E32: =NORMSINV(D32) -> -0.55959227
B33: =lns!D37 -> -0.36817221 | C33: 30 | D33: =(C33-0.5)/99 -> 0.2979798 | E33: =NORMSINV(D33) -> -0.53021973
B34: =lns!D43 -> -0.35284087 | C34: 31 | D34: =(C34-0.5)/99 -> 0.30808081 | E34: =NORMSINV(D34) -> -0.50129771
B35: =lns!D46 -> -0.350913 | C35: 32 | D35: =(C35-0.5)/99 -> 0.31818182 | E35: =NORMSINV(D35) -> -0.47278912
B36: =lns!D90 -> -0.33973074 | C36: 33 | D36: =(C36-0.5)/99 -> 0.32828283 | E36: =NORMSINV(D36) -> -0.44465976
B37: =lns!D48 -> -0.33528674 | C37: 34 | D37: =(C37-0.5)/99 -> 0.33838384 | E37: =NORMSINV(D37) -> -0.41687796
B38: =lns!D89 -> -0.30942202 | C38: 35 | D38: =(C38-0.5)/99 -> 0.34848485 | E38: =NORMSINV(D38) -> -0.3894143
B39: =lns!D91 -> -0.3008281 | C39: 36 | D39: =(C39-0.5)/99 -> 0.35858586 | E39: =NORMSINV(D39) -> -0.3622413
B40: =lns!D5 -> -0.2862005 | C40: 37 | D40: =(C40-0.5)/99 -> 0.36868687 | E40: =NORMSINV(D40) -> -0.33533322
B41: =lns!D27 -> -0.28438618 | C41: 38 | D41: =(C41-0.5)/99 -> 0.37878788 | E41: =NORMSINV(D41) -> -0.30866581
B42: =lns!D73 -> -0.27432238 | C42: 39 | D42: =(C42-0.5)/99 -> 0.38888889 | E42: =NORMSINV(D42) -> -0.28221615
...

Sheet Dec 4 Test
B3: Lns of Dec 4 Sorted | C3: Rank | D3: Rank Proportion | E3: Rank-Based Z Scores
B4: =lns!E41 -> -1.1022077 | C4: 1 | D4: =(C4-0.5)/99 -> 0.0050505051 | E4: =NORMSINV(D4) -> -2.5723521
B5: =lns!E42 -> -0.88684844 | C5: 2 | D5: =(C5-0.5)/99 -> 0.015151515 | E5: =NORMSINV(D5) -> -2.1661068
B6: =lns!E31 -> -0.85370803 | C6: 3 | D6: =(C6-0.5)/99 -> 0.025252525 | E6: =NORMSINV(D6) -> -1.9556614
B7: =lns!E44 -> -0.80504233 | C7: 4 | D7: =(C7-0.5)/99 -> 0.035353535 | E7: =NORMSINV(D7) -> -1.8073542
B8: =lns!E29 -> -0.80386647 | C8: 5 | D8: =(C8-0.5)/99 -> 0.045454545 | E8: =NORMSINV(D8) -> -1.6906216
B9: =lns!E35 -> -0.76760352 | C9: 6 | D9: =(C9-0.5)/99 -> 0.055555556 | E9: =NORMSINV(D9) -> -1.5932188
B10: =lns!E4 -> -0.75311589 | C10: 7 | D10: =(C10-0.5)/99 -> 0.065656566 | E10: =NORMSINV(D10) -> -1.5089439
B11: =lns!E94 -> -0.7386049 | C11: 8 | D11: =(C11-0.5)/99 -> 0.075757576 | E11: =NORMSINV(D11) -> -1.4342002
B12: =lns!E49 -> -0.72279435 | C12: 9 | D12: =(C12-0.5)/99 -> 0.085858586 | E12: =NORMSINV(D12) -> -1.366707
B13: =lns!E28 -> -0.71639943 | C13: 10 | D13: =(C13-0.5)/99 -> 0.095959596 | E13: =NORMSINV(D13) -> -1.3049226
B14: =lns!E40 -> -0.71459352 | C14: 11 | D14: =(C14-0.5)/99 -> 0.10606061 | E14: =NORMSINV(D14) -> -1.2477539
B15: =lns!E30 -> -0.70387856 | C15: 12 | D15: =(C15-0.5)/99 -> 0.11616162 | E15: =NORMSINV(D15) -> -1.1943957
B16: =lns!E72 -> -0.67508332 | C16: 13 | D16: =(C16-0.5)/99 -> 0.12626263 | E16: =NORMSINV(D16) -> -1.1442373
B17: =lns!E54 -> -0.66406033 | C17: 14 | D17: =(C17-0.5)/99 -> 0.13636364 | E17: =NORMSINV(D17) -> -1.0968036
B18: =lns!E21 -> -0.66302155 | C18: 15 | D18: =(C18-0.5)/99 -> 0.14646465 | E18: =NORMSINV(D18) -> -1.0517173
B19: =lns!E38 -> -0.64990763 | C19: 16 | D19: =(C19-0.5)/99 -> 0.15656566 | E19: =NORMSINV(D19) -> -1.0086734
B20: =lns!E36 -> -0.64310637 | C20: 17 | D20: =(C20-0.5)/99 -> 0.16666667 | E20: =NORMSINV(D20) -> -0.96742157
B21: =lns!E45 -> -0.62038755 | C21: 18 | D21: =(C21-0.5)/99 -> 0.17676768 | E21: =NORMSINV(D21) -> -0.92775369
B22: =lns!E33 -> -0.60621381 | C22: 19 | D22: =(C22-0.5)/99 -> 0.18686869 | E22: =NORMSINV(D22) -> -0.88949451
B23: =lns!E69 -> -0.57668235 | C23: 20 | D23: =(C23-0.5)/99 -> 0.1969697 | E23: =NORMSINV(D23) -> -0.85249503
B24: =lns!E70 -> -0.55375922 | C24: 21 | D24: =(C24-0.5)/99 -> 0.20707071 | E24: =NORMSINV(D24) -> -0.81662736
B25: =lns!E37 -> -0.51876035 | C25: 22 | D25: =(C25-0.5)/99 -> 0.21717172 | E25: =NORMSINV(D25) -> -0.78178075
B26: =lns!E62 -> -0.51394883 | C26: 23 | D26: =(C26-0.5)/99 -> 0.22727273 | E26: =NORMSINV(D26) -> -0.74785859
B27: =lns!E53 -> -0.47560971 | C27: 24 | D27: =(C27-0.5)/99 -> 0.23737374 | E27: =NORMSINV(D27) -> -0.71477599
B28: =lns!E71 -> -0.4510861 | C28: 25 | D28: =(C28-0.5)/99 -> 0.24747475 | E28: =NORMSINV(D28) -> -0.68245784
B29: =lns!E73 -> -0.44649025 | C29: 26 | D29: =(C29-0.5)/99 -> 0.25757576 | E29: =NORMSINV(D29) -> -0.65083731
B30: =lns!E22 -> -0.44074779 | C30: 27 | D30: =(C30-0.5)/99 -> 0.26767677 | E30: =NORMSINV(D30) -> -0.61985457
B31: =lns!E20 -> -0.41716529 | C31: 28 | D31: =(C31-0.5)/99 -> 0.27777778 | E31: =NORMSINV(D31) -> -0.5894558
B32: =lns!E43 -> -0.41215896 | C32: 29 | D32: =(C32-0.5)/99 -> 0.28787879 | E32: =NORMSINV(D32) -> -0.55959227
B33: =lns!E19 -> -0.39745676 | C33: 30 | D33: =(C33-0.5)/99 -> 0.2979798 | E33: =NORMSINV(D33) -> -0.53021973
B34: =lns!E32 -> -0.39096918 | C34: 31 | D34: =(C34-0.5)/99 -> 0.30808081 | E34: =NORMSINV(D34) -> -0.50129771
B35: =lns!E48 -> -0.35839929 | C35: 32 | D35: =(C35-0.5)/99 -> 0.31818182 | E35: =NORMSINV(D35) -> -0.47278912
B36: =lns!E46 -> -0.35752816 | C36: 33 | D36: =(C36-0.5)/99 -> 0.32828283 | E36: =NORMSINV(D36) -> -0.44465976
B37: =lns!E26 -> -0.34994762 | C37: 34 | D37: =(C37-0.5)/99 -> 0.33838384 | E37: =NORMSINV(D37) -> -0.41687796
B38: =lns!E82 -> -0.34902429 | C38: 35 | D38: =(C38-0.5)/99 -> 0.34848485 | E38: =NORMSINV(D38) -> -0.3894143
B39: =lns!E90 -> -0.34794459 | C39: 36 | D39: =(C39-0.5)/99 -> 0.35858586 | E39: =NORMSINV(D39) -> -0.3622413
B40: =lns!E56 -> -0.34381795 | C40: 37 | D40: =(C40-0.5)/99 -> 0.36868687 | E40: =NORMSINV(D40) -> -0.33533322
B41: =lns!E83 -> -0.33491625 | C41: 38 | D41: =(C41-0.5)/99 -> 0.37878788 | E41: =NORMSINV(D41) -> -0.30866581
B42: =lns!E66 -> -0.33269478 | C42: 39 | D42: =(C42-0.5)/99 -> 0.38888889 | E42: =NORMSINV(D42) -> -0.28221615
...

Sheet Dec 5 Test
A1: \
B3: Lns of Dec 5 Sorted | C3: Rank | D3: Rank Proportion | E3: Rank-Based Z Scores
B4: =lns!F29 -> -1.0905608 | C4: 1 | D4: =(C4-0.5)/99 -> 0.0050505051 | E4: =NORMSINV(D4) -> -2.5723521
B5: =lns!F41 -> -0.99491195 | C5: 2 | D5: =(C5-0.5)/99 -> 0.015151515 | E5: =NORMSINV(D5) -> -2.1661068
B6: =lns!F54 -> -0.7920199 | C6: 3 | D6: =(C6-0.5)/99 -> 0.025252525 | E6: =NORMSINV(D6) -> -1.9556614
B7: =lns!F42 -> -0.76937833 | C7: 4 | D7: =(C7-0.5)/99 -> 0.035353535 | E7: =NORMSINV(D7) -> -1.8073542
B8: =lns!F21 -> -0.74866623 | C8: 5 | D8: =(C8-0.5)/99 -> 0.045454545 | E8: =NORMSINV(D8) -> -1.6906216
B9: =lns!F26 -> -0.73068707 | C9: 6 | D9: =(C9-0.5)/99 -> 0.055555556 | E9: =NORMSINV(D9) -> -1.5932188
B10: =lns!F30 -> -0.72820664 | C10: 7 | D10: =(C10-0.5)/99 -> 0.065656566 | E10: =NORMSINV(D10) -> -1.5089439
B11: =lns!F72 -> -0.69957781 | C11: 8 | D11: =(C11-0.5)/99 -> 0.075757576 | E11: =NORMSINV(D11) -> -1.4342002
B12: =lns!F49 -> -0.69020751 | C12: 9 | D12: =(C12-0.5)/99 -> 0.085858586 | E12: =NORMSINV(D12) -> -1.366707
B13: =lns!F94 -> -0.68791489 | C13: 10 | D13: =(C13-0.5)/99 -> 0.095959596 | E13: =NORMSINV(D13) -> -1.3049226
B14: =lns!F70 -> -0.66539778 | C14: 11 | D14: =(C14-0.5)/99 -> 0.10606061 | E14: =NORMSINV(D14) -> -1.2477539
B15: =lns!F4 -> -0.66265677 | C15: 12 | D15: =(C15-0.5)/99 -> 0.11616162 | E15: =NORMSINV(D15) -> -1.1943957
B16: =lns!F45 -> -0.65692712 | C16: 13 | D16: =(C16-0.5)/99 -> 0.12626263 | E16: =NORMSINV(D16) -> -1.1442373
B17: =lns!F44 -> -0.6411925 | C17: 14 | D17: =(C17-0.5)/99 -> 0.13636364 | E17: =NORMSINV(D17) -> -1.0968036
B18: =lns!F40 -> -0.63965002 | C18: 15 | D18: =(C18-0.5)/99 -> 0.14646465 | E18: =NORMSINV(D18) -> -1.0517173
B19: =lns!F36 -> -0.59704277 | C19: 16 | D19: =(C19-0.5)/99 -> 0.15656566 | E19: =NORMSINV(D19) -> -1.0086734
B20: =lns!F71 -> -0.59467473 | C20: 17 | D20: =(C20-0.5)/99 -> 0.16666667 | E20: =NORMSINV(D20) -> -0.96742157
B21: =lns!F31 -> -0.590522 | C21: 18 | D21: =(C21-0.5)/99 -> 0.17676768 | E21: =NORMSINV(D21) -> -0.92775369
B22: =lns!F25 -> -0.56764645 | C22: 19 | D22: =(C22-0.5)/99 -> 0.18686869 | E22: =NORMSINV(D22) -> -0.88949451
B23: =lns!F69 -> -0.56459039 | C23: 20 | D23: =(C23-0.5)/99 -> 0.1969697 | E23: =NORMSINV(D23) -> -0.85249503
B24: =lns!F35 -> -0.56180493 | C24: 21 | D24: =(C24-0.5)/99 -> 0.20707071 | E24: =NORMSINV(D24) -> -0.81662736
B25: =lns!F38 -> -0.53145359 | C25: 22 | D25: =(C25-0.5)/99 -> 0.21717172 | E25: =NORMSINV(D25) -> -0.78178075
B26: =lns!F53 -> -0.50009177 | C26: 23 | D26: =(C26-0.5)/99 -> 0.22727273 | E26: =NORMSINV(D26) -> -0.74785859
B27: =lns!F48 -> -0.47906375 | C27: 24 | D27: =(C27-0.5)/99 -> 0.23737374 | E27: =NORMSINV(D27) -> -0.71477599
B28: =lns!F37 -> -0.47463835 | C28: 25 | D28: =(C28-0.5)/99 -> 0.24747475 | E28: =NORMSINV(D28) -> -0.68245784
B29: =lns!F62 -> -0.4639818 | C29: 26 | D29: =(C29-0.5)/99 -> 0.25757576 | E29: =NORMSINV(D29) -> -0.65083731
B30: =lns!F28 -> -0.41846069 | C30: 27 | D30: =(C30-0.5)/99 -> 0.26767677 | E30: =NORMSINV(D30) -> -0.61985457
B31: =lns!F46 -> -0.40174255 | C31: 28 | D31: =(C31-0.5)/99 -> 0.27777778 | E31: =NORMSINV(D31) -> -0.5894558
B32: =lns!F22 -> -0.39488428 | C32: 29 | D32: =(C32-0.5)/99 -> 0.28787879 | E32: =NORMSINV(D32) -> -0.55959227
B33: =lns!F66 -> -0.37463236 | C33: 30 | D33: =(C33-0.5)/99 -> 0.2979798 | E33: =NORMSINV(D33) -> -0.53021973
B34: =lns!F33 -> -0.36689413 | C34: 31 | D34: =(C34-0.5)/99 -> 0.30808081 | E34: =NORMSINV(D34) -> -0.50129771
B35: =lns!F34 -> -0.35002283 | C35: 32 | D35: =(C35-0.5)/99 -> 0.31818182 | E35: =NORMSINV(D35) -> -0.47278912
B36: =lns!F73 -> -0.34160619 | C36: 33 | D36: =(C36-0.5)/99 -> 0.32828283 | E36: =NORMSINV(D36) -> -0.44465976
B37: =lns!F56 -> -0.32927381 | C37: 34 | D37: =(C37-0.5)/99 -> 0.33838384 | E37: =NORMSINV(D37) -> -0.41687796
B38: =lns!F55 -> -0.32289897 | C38: 35 | D38: =(C38-0.5)/99 -> 0.34848485 | E38: =NORMSINV(D38) -> -0.3894143
B39: =lns!F90 -> -0.31720152 | C39: 36 | D39: =(C39-0.5)/99 -> 0.35858586 | E39: =NORMSINV(D39) -> -0.3622413
B40: =lns!F19 -> -0.31626812 | C40: 37 | D40: =(C40-0.5)/99 -> 0.36868687 | E40: =NORMSINV(D40) -> -0.33533322
B41: =lns!F82 -> -0.31191739 | C41: 38 | D41: =(C41-0.5)/99 -> 0.37878788 | E41: =NORMSINV(D41) -> -0.30866581
...

Sheet Dec 6 Test
B3: Lns of Dec 6 Sorted | C3: Rank | D3: Rank Proportion | E3: Rank-Based Z Scores
B4: =lns!G41 -> -0.94641494 | C4: 1 | D4: =(C4-0.5)/99 -> 0.0050505051 | E4: =NORMSINV(D4) -> -2.5723521
B5: =lns!G54 -> -0.77116278 | C5: 2 | D5: =(C5-0.5)/99 -> 0.015151515 | E5: =NORMSINV(D5) -> -2.1661068
B6: =lns!G72 -> -0.75304582 | C6: 3 | D6: =(C6-0.5)/99 -> 0.025252525 | E6: =NORMSINV(D6) -> -1.9556614
B7: =lns!G42 -> -0.70917494 | C7: 4 | D7: =(C7-0.5)/99 -> 0.035353535 | E7: =NORMSINV(D7) -> -1.8073542
B8: =lns!G35 -> -0.68920297 | C8: 5 | D8: =(C8-0.5)/99 -> 0.045454545 | E8: =NORMSINV(D8) -> -1.6906216
B9: =lns!G4 -> -0.67026303 | C9: 6 | D9: =(C9-0.5)/99 -> 0.055555556 | E9: =NORMSINV(D9) -> -1.5932188
B10: =lns!G49 -> -0.66800394 | C10: 7 | D10: =(C10-0.5)/99 -> 0.065656566 | E10: =NORMSINV(D10) -> -1.5089439
B11: =lns!G70 -> -0.65712581 | C11: 8 | D11: =(C11-0.5)/99 -> 0.075757576 | E11: =NORMSINV(D11) -> -1.4342002
B12: =lns!G94 -> -0.65630044 | C12: 9 | D12: =(C12-0.5)/99 -> 0.085858586 | E12: =NORMSINV(D12) -> -1.366707
B13: =lns!G38 -> -0.64001977 | C13: 10 | D13: =(C13-0.5)/99 -> 0.095959596 | E13: =NORMSINV(D13) -> -1.3049226
B14: =lns!G21 -> -0.62800946 | C14: 11 | D14: =(C14-0.5)/99 -> 0.10606061 | E14: =NORMSINV(D14) -> -1.2477539
B15: =lns!G30 -> -0.61001816 | C15: 12 | D15: =(C15-0.5)/99 -> 0.11616162 | E15: =NORMSINV(D15) -> -1.1943957
B16: =lns!G69 -> -0.59288022 | C16: 13 | D16: =(C16-0.5)/99 -> 0.12626263 | E16: =NORMSINV(D16) -> -1.1442373
B17: =lns!G44 -> -0.58294122 | C17: 14 | D17: =(C17-0.5)/99 -> 0.13636364 | E17: =NORMSINV(D17) -> -1.0968036
B18: =lns!G29 -> -0.57281806 | C18: 15 | D18: =(C18-0.5)/99 -> 0.14646465 | E18: =NORMSINV(D18) -> -1.0517173
B19: =lns!G45 -> -0.5722809 | C19: 16 | D19: =(C19-0.5)/99 -> 0.15656566 | E19: =NORMSINV(D19) -> -1.0086734
B20: =lns!G31 -> -0.5503065 | C20: 17 | D20: =(C20-0.5)/99 -> 0.16666667 | E20: =NORMSINV(D20) -> -0.96742157
B21: =lns!G36 -> -0.53695573 | C21: 18 | D21: =(C21-0.5)/99 -> 0.17676768 | E21: =NORMSINV(D21) -> -0.92775369
B22: =lns!G71 -> -0.53635884 | C22: 19 | D22: =(C22-0.5)/99 -> 0.18686869 | E22: =NORMSINV(D22) -> -0.88949451
B23: =lns!G33 -> -0.52578699 | C23: 20 | D23: =(C23-0.5)/99 -> 0.1969697 | E23: =NORMSINV(D23) -> -0.85249503
B24: =lns!G62 -> -0.52501921 | C24: 21 | D24: =(C24-0.5)/99 -> 0.20707071 | E24: =NORMSINV(D24) -> -0.81662736
B25: =lns!G24 -> -0.50461329 | C25: 22 | D25: =(C25-0.5)/99 -> 0.21717172 | E25: =NORMSINV(D25) -> -0.78178075
B26: =lns!G26 -> -0.48681129 | C26: 23 | D26: =(C26-0.5)/99 -> 0.22727273 | E26: =NORMSINV(D26) -> -0.74785859
B27: =lns!G40 -> -0.47679464 | C27: 24 | D27: =(C27-0.5)/99 -> 0.23737374 | E27: =NORMSINV(D27) -> -0.71477599
B28: =lns!G55 -> -0.47355392 | C28: 25 | D28: =(C28-0.5)/99 -> 0.24747475 | E28: =NORMSINV(D28) -> -0.68245784
B29: =lns!G48 -> -0.47000683 | C29: 26 | D29: =(C29-0.5)/99 -> 0.25757576 | E29: =NORMSINV(D29) -> -0.65083731
B30: =lns!G56 -> -0.46749638 | C30: 27 | D30: =(C30-0.5)/99 -> 0.26767677 | E30: =NORMSINV(D30) -> -0.61985457
B31: =lns!G37 -> -0.46338717 | C31: 28 | D31: =(C31-0.5)/99 -> 0.27777778 | E31: =NORMSINV(D31) -> -0.5894558
B32: =lns!G53 -> -0.45295931 | C32: 29 | D32: =(C32-0.5)/99 -> 0.28787879 | E32: =NORMSINV(D32) -> -0.55959227
B33: =lns!G34 -> -0.45157449 | C33: 30 | D33: =(C33-0.5)/99 -> 0.2979798 | E33: =NORMSINV(D33) -> -0.53021973
B34: =lns!G22 -> -0.44227329 | C34: 31 | D34: =(C34-0.5)/99 -> 0.30808081 | E34: =NORMSINV(D34) -> -0.50129771
B35: =lns!G73 -> -0.41050981 | C35: 32 | D35: =(C35-0.5)/99 -> 0.31818182 | E35: =NORMSINV(D35) -> -0.47278912
B36: =lns!G28 -> -0.37736903 | C36: 33 | D36: =(C36-0.5)/99 -> 0.32828283 | E36: =NORMSINV(D36) -> -0.44465976
B37: =lns!G83 -> -0.35764112 | C37: 34 | D37: =(C37-0.5)/99 -> 0.33838384 | E37: =NORMSINV(D37) -> -0.41687796
B38: =lns!G32 -> -0.33124254 | C38: 35 | D38: =(C38-0.5)/99 -> 0.34848485 | E38: =NORMSINV(D38) -> -0.3894143
B39: =lns!G5 -> -0.3287666 | C39: 36 | D39: =(C39-0.5)/99 -> 0.35858586 | E39: =NORMSINV(D39) -> -0.3622413
B40: =lns!G90 -> -0.32724514 | C40: 37 | D40: =(C40-0.5)/99 -> 0.36868687 | E40: =NORMSINV(D40) -> -0.33533322
B41: =lns!G61 -> -0.31750918 | C41: 38 | D41: =(C41-0.5)/99 -> 0.37878788 | E41: =NORMSINV(D41) -> -0.30866581
B42: =lns!G96 -> -0.31384263 | C42: 39 | D42: =(C42-0.5)/99 -> 0.38888889 | E42: =NORMSINV(D42) -> -0.28221615
...

Sheet Dec 7 Test
B3: Lns of Dec 7 Sorted | C3: Rank | D3: Rank Proportion | E3: Rank-Based Z Scores
B4: =lns!H41 -> -0.99859683 | C4: 1 | D4: =(C4-0.5)/99 -> 0.0050505051 | E4: =NORMSINV(D4) -> -2.5723521
B5: =lns!H38 -> -0.75154354 | C5: 2 | D5: =(C5-0.5)/99 -> 0.015151515 | E5: =NORMSINV(D5) -> -2.1661068
B6: =lns!H54 -> -0.74929223 | C6: 3 | D6: =(C6-0.5)/99 -> 0.025252525 | E6: =NORMSINV(D6) -> -1.9556614
B7: =lns!H72 -> -0.73033412 | C7: 4 | D7: =(C7-0.5)/99 -> 0.035353535 | E7: =NORMSINV(D7) -> -1.8073542
B8: =lns!H69 -> -0.70495057 | C8: 5 | D8: =(C8-0.5)/99 -> 0.045454545 | E8: =NORMSINV(D8) -> -1.6906216
B9: =lns!H94 -> -0.69064033 | C9: 6 | D9: =(C9-0.5)/99 -> 0.055555556 | E9: =NORMSINV(D9) -> -1.5932188
B10: =lns!H42 -> -0.65716633 | C10: 7 | D10: =(C10-0.5)/99 -> 0.065656566 | E10: =NORMSINV(D10) -> -1.5089439
B11: =lns!H49 -> -0.65509253 | C11: 8 | D11: =(C11-0.5)/99 -> 0.075757576 | E11: =NORMSINV(D11) -> -1.4342002
B12: =lns!H70 -> -0.64548146 | C12: 9 | D12: =(C12-0.5)/99 -> 0.085858586 | E12: =NORMSINV(D12) -> -1.366707
B13: =lns!H29 -> -0.63142387 | C13: 10 | D13: =(C13-0.5)/99 -> 0.095959596 | E13: =NORMSINV(D13) -> -1.3049226
B14: =lns!H40 -> -0.5984863 | C14: 11 | D14: =(C14-0.5)/99 -> 0.10606061 | E14: =NORMSINV(D14) -> -1.2477539
B15: =lns!H31 -> -0.59744435 | C15: 12 | D15: =(C15-0.5)/99 -> 0.11616162 | E15: =NORMSINV(D15) -> -1.1943957
B16: =lns!H44 -> -0.56395218 | C16: 13 | D16: =(C16-0.5)/99 -> 0.12626263 | E16: =NORMSINV(D16) -> -1.1442373
B17: =lns!H55 -> -0.55329307 | C17: 14 | D17: =(C17-0.5)/99 -> 0.13636364 | E17: =NORMSINV(D17) -> -1.0968036
B18: =lns!H35 -> -0.5397465 | C18: 15 | D18: =(C18-0.5)/99 -> 0.14646465 | E18: =NORMSINV(D18) -> -1.0517173
B19: =lns!H62 -> -0.53111677 | C19: 16 | D19: =(C19-0.5)/99 -> 0.15656566 | E19: =NORMSINV(D19) -> -1.0086734
B20: =lns!H71 -> -0.51732168 | C20: 17 | D20: =(C20-0.5)/99 -> 0.16666667 | E20: =NORMSINV(D20) -> -0.96742157
B21: =lns!H45 -> -0.50872783 | C21: 18 | D21: =(C21-0.5)/99 -> 0.17676768 | E21: =NORMSINV(D21) -> -0.92775369
B22: =lns!H30 -> -0.4724819 | C22: 19 | D22: =(C22-0.5)/99 -> 0.18686869 | E22: =NORMSINV(D22) -> -0.88949451
B23: =lns!H4 -> -0.47194792 | C23: 20 | D23: =(C23-0.5)/99 -> 0.1969697 | E23: =NORMSINV(D23) -> -0.85249503
B24: =lns!H37 -> -0.46585066 | C24: 21 | D24: =(C24-0.5)/99 -> 0.20707071 | E24: =NORMSINV(D24) -> -0.81662736
B25: =lns!H56 -> -0.46326955 | C25: 22 | D25: =(C25-0.5)/99 -> 0.21717172 | E25: =NORMSINV(D25) -> -0.78178075
B26: =lns!H48 -> -0.46289932 | C26: 23 | D26: =(C26-0.5)/99 -> 0.22727273 | E26: =NORMSINV(D26) -> -0.74785859
B27: =lns!H73 -> -0.4258811 | C27: 24 | D27: =(C27-0.5)/99 -> 0.23737374 | E27: =NORMSINV(D27) -> -0.71477599
B28: =lns!H5 -> -0.42158382 | C28: 25 | D28: =(C28-0.5)/99 -> 0.24747475 | E28: =NORMSINV(D28) -> -0.68245784
B29: =lns!H36 -> -0.41987341 | C29: 26 | D29: =(C29-0.5)/99 -> 0.25757576 | E29: =NORMSINV(D29) -> -0.65083731
B30: =lns!H53 -> -0.38443382 | C30: 27 | D30: =(C30-0.5)/99 -> 0.26767677 | E30: =NORMSINV(D30) -> -0.61985457
B31: =lns!H46 -> -0.37861093 | C31: 28 | D31: =(C31-0.5)/99 -> 0.27777778 | E31: =NORMSINV(D31) -> -0.5894558
B32: =lns!H83 -> -0.37544137 | C32: 29 | D32: =(C32-0.5)/99 -> 0.28787879 | E32: =NORMSINV(D32) -> -0.55959227
B33: =lns!H61 -> -0.3734041 | C33: 30 | D33: =(C33-0.5)/99 -> 0.2979798 | E33: =NORMSINV(D33) -> -0.53021973
B34: =lns!H82 -> -0.36798437 | C34: 31 | D34: =(C34-0.5)/99 -> 0.30808081 | E34: =NORMSINV(D34) -> -0.50129771
B35: =lns!H66 -> -0.33713285 | C35: 32 | D35: =(C35-0.5)/99 -> 0.31818182 | E35: =NORMSINV(D35) -> -0.47278912
B36: =lns!H89 -> -0.31630105 | C36: 33 | D36: =(C36-0.5)/99 -> 0.32828283 | E36: =NORMSINV(D36) -> -0.44465976
B37: =lns!H90 -> -0.30489877 | C37: 34 | D37: =(C37-0.5)/99 -> 0.33838384 | E37: =NORMSINV(D37) -> -0.41687796
B38: =lns!H26 -> -0.2923034 | C38: 35 | D38: =(C38-0.5)/99 -> 0.34848485 | E38: =NORMSINV(D38) -> -0.3894143
B39: =lns!H81 -> -0.28776208 | C39: 36 | D39: =(C39-0.5)/99 -> 0.35858586 | E39: =NORMSINV(D39) -> -0.3622413
B40: =lns!H58 -> -0.28061643 | C40: 37 | D40: =(C40-0.5)/99 -> 0.36868687 | E40: =NORMSINV(D40) -> -0.33533322
B41: =lns!H60 -> -0.27257411 | C41: 38 | D41: =(C41-0.5)/99 -> 0.37878788 | E41: =NORMSINV(D41) -> -0.30866581
B42: =lns!H24 -> -0.27198722 | C42: 39 | D42: =(C42-0.5)/99 -> 0.38888889 | E42: =NORMSINV(D42) -> -0.28221615
...

Sheet Dec 8 Test
B3: Lns of Dec 8 Sorted | C3: Rank | D3: Rank Proportion | E3: Rank-Based Z Scores
B4: =lns!I54 -> -0.69897211 | C4: 1 | D4: =(C4-0.5)/99 -> 0.0050505051 | E4: =NORMSINV(D4) -> -2.5723521
B5: =lns!I49 -> -0.68939224 | C5: 2 | D5: =(C5-0.5)/99 -> 0.015151515 | E5: =NORMSINV(D5) -> -2.1661068
B6: =lns!I70 -> -0.68107633 | C6: 3 | D6: =(C6-0.5)/99 -> 0.025252525 | E6: =NORMSINV(D6) -> -1.9556614
B7: =lns!I42 -> -0.65909751 | C7: 4 | D7: =(C7-0.5)/99 -> 0.035353535 | E7: =NORMSINV(D7) -> -1.8073542
B8: =lns!I62 -> -0.62475235 | C8: 5 | D8: =(C8-0.5)/99 -> 0.045454545 | E8: =NORMSINV(D8) -> -1.6906216
B9: =lns!I29 -> -0.62275396 | C9: 6 | D9: =(C9-0.5)/99 -> 0.055555556 | E9: =NORMSINV(D9) -> -1.5932188
B10: =lns!I38 -> -0.61222363 | C10: 7 | D10: =(C10-0.5)/99 -> 0.065656566 | E10: =NORMSINV(D10) -> -1.5089439
B11: =lns!I72 -> -0.58756449 | C11: 8 | D11: =(C11-0.5)/99 -> 0.075757576 | E11: =NORMSINV(D11) -> -1.4342002
B12: =lns!I69 -> -0.57785257 | C12: 9 | D12: =(C12-0.5)/99 -> 0.085858586 | E12: =NORMSINV(D12) -> -1.366707
B13: =lns!I41 -> -0.52051407 | C13: 10 | D13: =(C13-0.5)/99 -> 0.095959596 | E13: =NORMSINV(D13) -> -1.3049226
B14: =lns!I44 -> -0.50189562 | C14: 11 | D14: =(C14-0.5)/99 -> 0.10606061 | E14: =NORMSINV(D14) -> -1.2477539
B15: =lns!I94 -> -0.4998725 | C15: 12 | D15: =(C15-0.5)/99 -> 0.11616162 | E15: =NORMSINV(D15) -> -1.1943957
B16: =lns!I71 -> -0.49405045 | C16: 13 | D16: =(C16-0.5)/99 -> 0.12626263 | E16: =NORMSINV(D16) -> -1.1442373
B17: =lns!I48 -> -0.46128812 | C17: 14 | D17: =(C17-0.5)/99 -> 0.13636364 | E17: =NORMSINV(D17) -> -1.0968036
B18: =lns!I55 -> -0.45649686 | C18: 15 | D18: =(C18-0.5)/99 -> 0.14646465 | E18: =NORMSINV(D18) -> -1.0517173
B19: =lns!I30 -> -0.45271868 | C19: 16 | D19: =(C19-0.5)/99 -> 0.15656566 | E19: =NORMSINV(D19) -> -1.0086734
B20: =lns!I56 -> -0.44976659 | C20: 17 | D20: =(C20-0.5)/99 -> 0.16666667 | E20: =NORMSINV(D20) -> -0.96742157
B21: =lns!I83 -> -0.44768652 | C21: 18 | D21: =(C21-0.5)/99 -> 0.17676768 | E21: =NORMSINV(D21) -> -0.92775369
B22: =lns!I35 -> -0.43834994 | C22: 19 | D22: =(C22-0.5)/99 -> 0.18686869 | E22: =NORMSINV(D22) -> -0.88949451
B23: =lns!I45 -> -0.42835663 | C23: 20 | D23: =(C23-0.5)/99 -> 0.1969697 | E23: =NORMSINV(D23) -> -0.85249503
B24: =lns!I33 -> -0.41958432 | C24: 21 | D24: =(C24-0.5)/99 -> 0.20707071 | E24: =NORMSINV(D24) -> -0.81662736
B25: =lns!I4 -> -0.41306995 | C25: 22 | D25: =(C25-0.5)/99 -> 0.21717172 | E25: =NORMSINV(D25) -> -0.78178075
B26: =lns!I61 -> -0.40685457 | C26: 23 | D26: =(C26-0.5)/99 -> 0.22727273 | E26: =NORMSINV(D26) -> -0.74785859
B27: =lns!I58 -> -0.40491126 | C27: 24 | D27: =(C27-0.5)/99 -> 0.23737374 | E27: =NORMSINV(D27) -> -0.71477599
B28: =lns!I66 -> -0.39946017 | C28: 25 | D28: =(C28-0.5)/99 -> 0.24747475 | E28: =NORMSINV(D28) -> -0.68245784
B29: =lns!I36 -> -0.39671302 | C29: 26 | D29: =(C29-0.5)/99 -> 0.25757576 | E29: =NORMSINV(D29) -> -0.65083731
B30: =lns!I37 -> -0.388785 | C30: 27 | D30: =(C30-0.5)/99 -> 0.26767677 | E30: =NORMSINV(D30) -> -0.61985457
B31: =lns!I82 -> -0.37504988 | C31: 28 | D31: =(C31-0.5)/99 -> 0.27777778 | E31: =NORMSINV(D31) -> -0.5894558
B32: =lns!I46 -> -0.37292919 | C32: 29 | D32: =(C32-0.5)/99 -> 0.28787879 | E32: =NORMSINV(D32) -> -0.55959227
B33: =lns!I73 -> -0.3627735 | C33: 30 | D33: =(C33-0.5)/99 -> 0.2979798 | E33: =NORMSINV(D33) -> -0.53021973
B34: =lns!I60 -> -0.34761044 | C34: 31 | D34: =(C34-0.5)/99 -> 0.30808081 | E34: =NORMSINV(D34) -> -0.50129771
B35: =lns!I21 -> -0.34759911 | C35: 32 | D35: =(C35-0.5)/99 -> 0.31818182 | E35: =NORMSINV(D35) -> -0.47278912
B36: =lns!I53 -> -0.30562475 | C36: 33 | D36: =(C36-0.5)/99 -> 0.32828283 | E36: =NORMSINV(D36) -> -0.44465976
B37: =lns!I91 -> -0.29186548 | C37: 34 | D37: =(C37-0.5)/99 -> 0.33838384 | E37: =NORMSINV(D37) -> -0.41687796
B38: =lns!I63 -> -0.28992726 | C38: 35 | D38: =(C38-0.5)/99 -> 0.34848485 | E38: =NORMSINV(D38) -> -0.3894143
B39: =lns!I31 -> -0.28758608 | C39: 36 | D39: =(C39-0.5)/99 -> 0.35858586 | E39: =NORMSINV(D39) -> -0.3622413
B40: =lns!I40 -> -0.28556565 | C40: 37 | D40: =(C40-0.5)/99 -> 0.36868687 | E40: =NORMSINV(D40) -> -0.33533322
B41: =lns!I28 -> -0.27369239 | C41: 38 | D41: =(C41-0.5)/99 -> 0.37878788 | E41: =NORMSINV(D41) -> -0.30866581
B42: =lns!I19 -> -0.24792304 | C42: 39 | D42: =(C42-0.5)/99 -> 0.38888889 | E42: =NORMSINV(D42) -> -0.28221615
...

Sheet Dec 9 Test
B3: Lns of Dec 9 Sorted | C3: Rank | D3: Rank Proportion | E3: Rank-Based Z Scores
B4: =lns!J41 -> -0.72436957 | C4: 1 | D4: =(C4-0.5)/99 -> 0.0050505051 | E4: =NORMSINV(D4) -> -2.5723521
B5: =lns!J54 -> -0.70606627 | C5: 2 | D5: =(C5-0.5)/99 -> 0.015151515 | E5: =NORMSINV(D5) -> -2.1661068
B6: =lns!J72 -> -0.65550271 | C6: 3 | D6: =(C6-0.5)/99 -> 0.025252525 | E6: =NORMSINV(D6) -> -1.9556614
B7: =lns!J38 -> -0.61386476 | C7: 4 | D7: =(C7-0.5)/99 -> 0.035353535 | E7: =NORMSINV(D7) -> -1.8073542
B8: =lns!J62 -> -0.60795529 | C8: 5 | D8: =(C8-0.5)/99 -> 0.045454545 | E8: =NORMSINV(D8) -> -1.6906216
B9: =lns!J29 -> -0.59222189 | C9: 6 | D9: =(C9-0.5)/99 -> 0.055555556 | E9: =NORMSINV(D9) -> -1.5932188
B10: =lns!J70 -> -0.52963305 | C10: 7 | D10: =(C10-0.5)/99 -> 0.065656566 | E10: =NORMSINV(D10) -> -1.5089439
B11: =lns!J42 -> -0.50394766 | C11: 8 | D11: =(C11-0.5)/99 -> 0.075757576 | E11: =NORMSINV(D11) -> -1.4342002
B12: =lns!J49 -> -0.50073834 | C12: 9 | D12: =(C12-0.5)/99 -> 0.085858586 | E12: =NORMSINV(D12) -> -1.366707
B13: =lns!J40 -> -0.44297385 | C13: 10 | D13: =(C13-0.5)/99 -> 0.095959596 | E13: =NORMSINV(D13) -> -1.3049226
B14: =lns!J69 -> -0.4404992 | C14: 11 | D14: =(C14-0.5)/99 -> 0.10606061 | E14: =NORMSINV(D14) -> -1.2477539
B15: =lns!J31 -> -0.43665396 | C15: 12 | D15: =(C15-0.5)/99 -> 0.11616162 | E15: =NORMSINV(D15) -> -1.1943957
B16: =lns!J73 -> -0.4206955 | C16: 13 | D16: =(C16-0.5)/99 -> 0.12626263 | E16: =NORMSINV(D16) -> -1.1442373
B17: =lns!J71 -> -0.40138245 | C17: 14 | D17: =(C17-0.5)/99 -> 0.13636364 | E17: =NORMSINV(D17) -> -1.0968036
B18: =lns!J44 -> -0.38181548 | C18: 15 | D18: =(C18-0.5)/99 -> 0.14646465 | E18: =NORMSINV(D18) -> -1.0517173
B19: =lns!J60 -> -0.37636321 | C19: 16 | D19: =(C19-0.5)/99 -> 0.15656566 | E19: =NORMSINV(D19) -> -1.0086734
B20: =lns!J36 -> -0.36976453 | C20: 17 | D20: =(C20-0.5)/99 -> 0.16666667 | E20: =NORMSINV(D20) -> -0.96742157
B21: =lns!J58 -> -0.36658243 | C21: 18 | D21: =(C21-0.5)/99 -> 0.17676768 | E21: =NORMSINV(D21) -> -0.92775369
B22: =lns!J66 -> -0.36116357 | C22: 19 | D22: =(C22-0.5)/99 -> 0.18686869 | E22: =NORMSINV(D22) -> -0.88949451
B23: =lns!J35 -> -0.34287348 | C23: 20 | D23: =(C23-0.5)/99 -> 0.1969697 | E23: =NORMSINV(D23) -> -0.85249503
B24: =lns!J83 -> -0.33884204 | C24: 21 | D24: =(C24-0.5)/99 -> 0.20707071 | E24: =NORMSINV(D24) -> -0.81662736
B25: =lns!J30 -> -0.32885691 | C25: 22 | D25: =(C25-0.5)/99 -> 0.21717172 | E25: =NORMSINV(D25) -> -0.78178075
B26: =lns!J76 -> -0.32596978 | C26: 23 | D26: =(C26-0.5)/99 -> 0.22727273 | E26: =NORMSINV(D26) -> -0.74785859
B27: =lns!J46 -> -0.32563042 | C27: 24 | D27: =(C27-0.5)/99 -> 0.23737374 | E27: =NORMSINV(D27) -> -0.71477599
B28: =lns!J33 -> -0.32070263 | C28: 25 | D28: =(C28-0.5)/99 -> 0.24747475 | E28: =NORMSINV(D28) -> -0.68245784
B29: =lns!J56 -> -0.31379062 | C29: 26 | D29: =(C29-0.5)/99 -> 0.25757576 | E29: =NORMSINV(D29) -> -0.65083731
B30: =lns!J45 -> -0.30818278 | C30: 27 | D30: =(C30-0.5)/99 -> 0.26767677 | E30: =NORMSINV(D30) -> -0.61985457
B31: =lns!J61 -> -0.30712588 | C31: 28 | D31: =(C31-0.5)/99 -> 0.27777778 | E31: =NORMSINV(D31) -> -0.5894558
B32: =lns!J82 -> -0.30632953 | C32: 29 | D32: =(C32-0.5)/99 -> 0.28787879 | E32: =NORMSINV(D32) -> -0.55959227
B33: =lns!J55 -> -0.30161874 | C33: 30 | D33: =(C33-0.5)/99 -> 0.2979798 | E33: =NORMSINV(D33) -> -0.53021973
B34: =lns!J94 -> -0.2946946 | C34: 31 | D34: =(C34-0.5)/99 -> 0.30808081 | E34: =NORMSINV(D34) -> -0.50129771
B35: =lns!J37 -> -0.29006224 | C35: 32 | D35: =(C35-0.5)/99 -> 0.31818182 | E35: =NORMSINV(D35) -> -0.47278912
B36: =lns!J91 -> -0.26267991 | C36: 33 | D36: =(C36-0.5)/99 -> 0.32828283 | E36: =NORMSINV(D36) -> -0.44465976
B37: =lns!J26 -> -0.25153274 | C37: 34 | D37: =(C37-0.5)/99 -> 0.33838384 | E37: =NORMSINV(D37) -> -0.41687796
B38: =lns!J53 -> -0.24705338 | C38: 35 | D38: =(C38-0.5)/99 -> 0.34848485 | E38: =NORMSINV(D38) -> -0.3894143
B39: =lns!J74 -> -0.23967317 | C39: 36 | D39: =(C39-0.5)/99 -> 0.35858586 | E39: =NORMSINV(D39) -> -0.3622413
B40: =lns!J67 -> -0.22500153 | C40: 37 | D40: =(C40-0.5)/99 -> 0.36868687 | E40: =NORMSINV(D40) -> -0.33533322
B41: =lns!J63 -> -0.2063946 | C41: 38 | D41: =(C41-0.5)/99 -> 0.37878788 | E41: =NORMSINV(D41) -> -0.30866581
B42: =lns!J34 -> -0.19752332 | C42: 39 | D42: =(C42-0.5)/99 -> 0.38888889 | E42: =NORMSINV(D42) -> -0.28221615
...

Sheet Hi 10 Test
B3: Lns of Hi 10 Sorted | C3: Rank | D3: Rank Proportion | E3: Rank-Based Z Scores
B4: =lns!K72 -> -0.78933655 | C4: 1 | D4: =(C4-0.5)/99 -> 0.0050505051 | E4: =NORMSINV(D4) -> -2.5723521
B5: =lns!K62 -> -0.66544641 | C5: 2 | D5: =(C5-0.5)/99 -> 0.015151515 | E5: =NORMSINV(D5) -> -2.1661068
B6: =lns!K41 -> -0.59442102 | C6: 3 | D6: =(C6-0.5)/99 -> 0.025252525 | E6: =NORMSINV(D6) -> -1.9556614
B7: =lns!K71 -> -0.55911117 | C7: 4 | D7: =(C7-0.5)/99 -> 0.035353535 | E7: =NORMSINV(D7) -> -1.8073542
B8: =lns!K66 -> -0.50397084 | C8: 5 | D8: =(C8-0.5)/99 -> 0.045454545 | E8: =NORMSINV(D8) -> -1.6906216
B9: =lns!K73 -> -0.45065287 | C9: 6 | D9: =(C9-0.5)/99 -> 0.055555556 | E9: =NORMSINV(D9) -> -1.5932188
B10: =lns!K54 -> -0.44875107 | C10: 7 | D10: =(C10-0.5)/99 -> 0.065656566 | E10: =NORMSINV(D10) -> -1.5089439
B11: =lns!K44 -> -0.44085656 | C11: 8 | D11: =(C11-0.5)/99 -> 0.075757576 | E11: =NORMSINV(D11) -> -1.4342002
B12: =lns!K42 -> -0.43904775 | C12: 9 | D12: =(C12-0.5)/99 -> 0.085858586 | E12: =NORMSINV(D12) -> -1.366707
B13: =lns!K49 -> -0.40099412 | C13: 10 | D13: =(C13-0.5)/99 -> 0.095959596 | E13: =NORMSINV(D13) -> -1.3049226
B14: =lns!K46 -> -0.38099106 | C14: 11 | D14: =(C14-0.5)/99 -> 0.10606061 | E14: =NORMSINV(D14) -> -1.2477539
B15: =lns!K40 -> -0.38069689 | C15: 12 | D15: =(C15-0.5)/99 -> 0.11616162 | E15: =NORMSINV(D15) -> -1.1943957
B16: =lns!K61 -> -0.37630639 | C16: 13 | D16: =(C16-0.5)/99 -> 0.12626263 | E16: =NORMSINV(D16) -> -1.1442373
B17: =lns!K45 -> -0.35794146 | C17: 14 | D17: =(C17-0.5)/99 -> 0.13636364 | E17: =NORMSINV(D17) -> -1.0968036
B18: =lns!K83 -> -0.35143015 | C18: 15 | D18: =(C18-0.5)/99 -> 0.14646465 | E18: =NORMSINV(D18) -> -1.0517173
B19: =lns!K82 -> -0.31280434 | C19: 16 | D19: =(C19-0.5)/99 -> 0.15656566 | E19: =NORMSINV(D19) -> -1.0086734
B20: =lns!K38 -> -0.30971911 | C20: 17 | D20: =(C20-0.5)/99 -> 0.16666667 | E20: =NORMSINV(D20) -> -0.96742157
B21: =lns!K58 -> -0.3036597 | C21: 18 | D21: =(C21-0.5)/99 -> 0.17676768 | E21: =NORMSINV(D21) -> -0.92775369
B22: =lns!K65 -> -0.27496593 | C22: 19 | D22: =(C22-0.5)/99 -> 0.18686869 | E22: =NORMSINV(D22) -> -0.88949451
B23: =lns!K70 -> -0.26445916 | C23: 20 | D23: =(C23-0.5)/99 -> 0.1969697 | E23: =NORMSINV(D23) -> -0.85249503
B24: =lns!K60 -> -0.25151731 | C24: 21 | D24: =(C24-0.5)/99 -> 0.20707071 | E24: =NORMSINV(D24) -> -0.81662736
B25: =lns!K33 -> -0.24077431 | C25: 22 | D25: =(C25-0.5)/99 -> 0.21717172 | E25: =NORMSINV(D25) -> -0.78178075
B26: =lns!K29 -> -0.23897445 | C26: 23 | D26: =(C26-0.5)/99 -> 0.22727273 | E26: =NORMSINV(D26) -> -0.74785859
B27: =lns!K31 -> -0.23360306 | C27: 24 | D27: =(C27-0.5)/99 -> 0.23737374 | E27: =NORMSINV(D27) -> -0.71477599
B28: =lns!K63 -> -0.20796927 | C28: 25 | D28: =(C28-0.5)/99 -> 0.24747475 | E28: =NORMSINV(D28) -> -0.68245784
B29: =lns!K36 -> -0.19956742 | C29: 26 | D29: =(C29-0.5)/99 -> 0.25757576 | E29: =NORMSINV(D29) -> -0.65083731
B30: =lns!K76 -> -0.18807809 | C30: 27 | D30: =(C30-0.5)/99 -> 0.26767677 | E30: =NORMSINV(D30) -> -0.61985457
B31: =lns!K37 -> -0.17963756 | C31: 28 | D31: =(C31-0.5)/99 -> 0.27777778 | E31: =NORMSINV(D31) -> -0.5894558
B32: =lns!K56 -> -0.17373572 | C32: 29 | D32: =(C32-0.5)/99 -> 0.28787879 | E32: =NORMSINV(D32) -> -0.55959227
B33: =lns!K74 -> -0.17034121 | C33: 30 | D33: =(C33-0.5)/99 -> 0.2979798 | E33: =NORMSINV(D33) -> -0.53021973
B34: =lns!K35 -> -0.1509101 | C34: 31 | D34: =(C34-0.5)/99 -> 0.30808081 | E34: =NORMSINV(D34) -> -0.50129771
B35: =lns!K59 -> -0.09224907 | C35: 32 | D35: =(C35-0.5)/99 -> 0.31818182 | E35: =NORMSINV(D35) -> -0.47278912
B36: =lns!K67 -> -0.06188817 | C36: 33 | D36: =(C36-0.5)/99 -> 0.32828283 | E36: =NORMSINV(D36) -> -0.44465976
B37: =lns!K43 -> -0.048786964 | C37: 34 | D37: =(C37-0.5)/99 -> 0.33838384 | E37: =NORMSINV(D37) -> -0.41687796
B38: =lns!K30 -> -0.046563445 | C38: 35 | D38: =(C38-0.5)/99 -> 0.34848485 | E38: =NORMSINV(D38) -> -0.3894143
B39: =lns!K91 -> -0.044994228 | C39: 36 | D39: =(C39-0.5)/99 -> 0.35858586 | E39: =NORMSINV(D39) -> -0.3622413
B40: =lns!K94 -> -0.04139716 | C40: 37 | D40: =(C40-0.5)/99 -> 0.36868687 | E40: =NORMSINV(D40) -> -0.33533322
B41: =lns!K55 -> -0.039825616 | C41: 38 | D41: =(C41-0.5)/99 -> 0.37878788 | E41: =NORMSINV(D41) -> -0.30866581
B42: =lns!K53 -> -0.013098411 | C42: 39 | D42: =(C42-0.5)/99 -> 0.38888889 | E42: =NORMSINV(D42) -> -0.28221615
...
